Workbook

Sheet 1. Journaal
A1: MetWear bv - journaal 1e kwartaal 2026
A3: Ref | B3: Datum | C3: Rekening | D3: Naam rekening | E3: Debet | F3: Credit | G3: Toelichting
A4: BEGINBALANS | B4: 46023 | C4: 221000 | D4: Gebouwen | E4: 400000 | G4: Beginbalans 1 januari 2026
A5: BEGINBALANS | B5: 46023 | C5: 221009 | D5: Afschrijvingen op gebouwen (-) | F5: 160000 | G5: Beginbalans 1 januari 2026
A6: BEGINBALANS | B6: 46023 | C6: 230000 | D6: Installaties | E6: 100000 | G6: Beginbalans 1 januari 2026
A7: BEGINBALANS | B7: 46023 | C7: 230009 | D7: Afschrijvingen op installaties (-) | F7: 70000 | G7: Beginbalans 1 januari 2026
A8: BEGINBALANS | B8: 46023 | C8: 240000 | D8: Meubilair | E8: 60000 | G8: Beginbalans 1 januari 2026
A9: BEGINBALANS | B9: 46023 | C9: 240009 | D9: Afschrijvingen op meubilair (-) | F9: 30000 | G9: Beginbalans 1 januari 2026
A10: BEGINBALANS | B10: 46023 | C10: 241000 | D10: Rollend materieel | E10: 50000 | G10: Beginbalans 1 januari 2026
A11: BEGINBALANS | B11: 46023 | C11: 241009 | D11: Afschrijvingen op rollend materieel (-) | F11: 40000 | G11: Beginbalans 1 januari 2026
A12: BEGINBALANS | B12: 46023 | C12: 340000 | D12: Voorraad handelsgoederen | E12: 100000 | G12: Beginbalans 1 januari 2026
A13: BEGINBALANS | B13: 46023 | C13: 400000 | D13: Handelsdebiteuren | E13: 60000 | G13: Beginbalans 1 januari 2026
A14: BEGINBALANS | B14: 46023 | C14: 550000 | D14: Bankrekening | E14: 70000 | G14: Beginbalans 1 januari 2026
A15: BEGINBALANS | B15: 46023 | C15: 570000 | D15: Kas | E15: 2000 | G15: Beginbalans 1 januari 2026
A16: BEGINBALANS | B16: 46023 | C16: 100000 | D16: Geplaatst kapitaal | F16: 350000 | G16: Beginbalans 1 januari 2026
A17: BEGINBALANS | B17: 46023 | C17: 130000 | D17: Wettelijke reserve | F17: 50000 | G17: Beginbalans 1 januari 2026
A18: BEGINBALANS | B18: 46023 | C18: 140000 | D18: Overgedragen winst | F18: 40000 | G18: Beginbalans 1 januari 2026
A19: BEGINBALANS | B19: 46023 | C19: 440000 | D19: Leveranciers | F19: =50000+22000 -> 72000 | G19: Beginbalans 1 januari 2026
A20: BEGINBALANS | B20: 46023 | C20: 451000 | D20: Te betalen btw-saldo | F20: 12000 | G20: Beginbalans 1 januari 2026
A21: BEGINBALANS | B21: 46023 | C21: 455200 | D21: Verschuldigde lonen bedienden | F21: 13000 | G21: Beginbalans 1 januari 2026
A22: BEGINBALANS | B22: 46023 | C22: 455300 | D22: Verschuldigde lonen arbeiders | F22: 5000 | G22: Beginbalans 1 januari 2026
A23: VK01 | B23: 46025 | C23: 704000 | D23: Verkopen handelsgoederen | F23: 24000 | G23: Verkoopfactuur 2026-01 - Concept Store Nova bv
A24: VK01 | B24: 46025 | C24: 704020 | D24: Handelskorting op verkopen (-) | E24: 2400 | G24: Verkoopfactuur 2026-01 - Concept Store Nova bv
A25: VK01 | B25: 46025 | C25: 451100 | D25: Verschuldigde btw | F25: 4536 | G25: Verkoopfactuur 2026-01 - Concept Store Nova bv
A26: VK01 | B26: 46025 | C26: 400000 | D26: Handelsdebiteuren | E26: 26136 | G26: Verkoopfactuur 2026-01 - Concept Store Nova bv
A27: VK02 | B27: 46032 | C27: 704000 | D27: Verkopen handelsgoederen | F27: 18000 | G27: Verkoopfactuur 2026-02 - Kringwinkel De Draad vzw
A28: VK02 | B28: 46032 | C28: 704000 | D28: Verkopen handelsgoederen | F28: 3000 | G28: Verkoopfactuur 2026-02 - Kringwinkel De Draad vzw
A29: VK02 | B29: 46032 | C29: 451100 | D29: Verschuldigde btw | F29: 3780 | G29: Verkoopfactuur 2026-02 - Kringwinkel De Draad vzw
A30: VK02 | B30: 46032 | C30: 451100 | D30: Verschuldigde btw | F30: 180 | G30: Verkoopfactuur 2026-02 - Kringwinkel De Draad vzw
A31: VK02 | B31: 46032 | C31: 400000 | D31: Handelsdebiteuren | E31: 24960 | G31: Verkoopfactuur 2026-02 - Kringwinkel De Draad vzw
A32: VK03 | B32: 46039 | C32: 704000 | D32: Verkopen handelsgoederen | F32: 30000 | G32: Verkoopfactuur 2026-03 - Modehuis Vandeputte bv
A33: VK03 | B33: 46039 | C33: 746000 | D33: Doorgerekende kosten | F33: 600 | G33: Verkoopfactuur 2026-03 - Modehuis Vandeputte bv
A34: VK03 | B34: 46039 | C34: 451100 | D34: Verschuldigde btw | F34: 6426 | G34: Verkoopfactuur 2026-03 - Modehuis Vandeputte bv
A35: VK03 | B35: 46039 | C35: 488000 | D35: Terug te betalen verpakking | F35: 500 | G35: Verkoopfactuur 2026-03 - Modehuis Vandeputte bv
A36: VK03 | B36: 46039 | C36: 400000 | D36: Handelsdebiteuren | E36: 37526 | G36: Verkoopfactuur 2026-03 - Modehuis Vandeputte bv
A37: VK04 | B37: 46057 | C37: 488000 | D37: Terug te betalen verpakking | E37: 500 | G37: Creditnota 2026-04 - Modehuis Vandeputte bv - teruggestuurde verpakking
A38: VK04 | B38: 46057 | C38: 400000 | D38: Handelsdebiteuren | F38: 500 | G38: Creditnota 2026-04 - Modehuis Vandeputte bv - teruggestuurde verpakking
A39: VK05 | B39: 46061 | C39: 704000 | D39: Verkopen handelsgoederen | F39: 40000 | G39: Verkoopfactuur 2026-05 - Boetiek Lumen bv
A40: VK05 | B40: 46061 | C40: 451100 | D40: Verschuldigde btw | F40: 8232 | G40: Verkoopfactuur 2026-05 - Boetiek Lumen bv
A41: VK05 | B41: 46061 | C41: 400000 | D41: Handelsdebiteuren | E41: 48232 | G41: Verkoopfactuur 2026-05 - Boetiek Lumen bv
...

Sheet 2. Proef- en saldibalans
A1: Proef- en saldibalans 31 maart 2026
A3: Rekening | B3: Naam rekening | C3: Soort | D3: Debettotaal | E3: Credittotaal | F3: Debetsaldo | G3: Creditsaldo
A4: 100000 | B4: Geplaatst kapitaal | C4: Passief | D4: =SUMIF('1. Journaal'!$C$4:$C$186,$A4,'1. Journaal'!$E$4:$E$186) -> 0 | E4: =SUMIF('1. Journaal'!$C$4:$C$186,$A4,'1. Journaal'!$F$4:$F$186) -> 350000 | F4: =IF(D4-E4>0,D4-E4,0) -> 0 | G4: =IF(E4-D4>0,E4-D4,0) -> 350000
A5: 130000 | B5: Wettelijke reserve | C5: Passief | D5: =SUMIF('1. Journaal'!$C$4:$C$186,$A5,'1. Journaal'!$E$4:$E$186) -> 0 | E5: =SUMIF('1. Journaal'!$C$4:$C$186,$A5,'1. Journaal'!$F$4:$F$186) -> 50000 | F5: =IF(D5-E5>0,D5-E5,0) -> 0 | G5: =IF(E5-D5>0,E5-D5,0) -> 50000
A6: 140000 | B6: Overgedragen winst | C6: Passief | D6: =SUMIF('1. Journaal'!$C$4:$C$186,$A6,'1. Journaal'!$E$4:$E$186) -> 0 | E6: =SUMIF('1. Journaal'!$C$4:$C$186,$A6,'1. Journaal'!$F$4:$F$186) -> 47784 | F6: =IF(D6-E6>0,D6-E6,0) -> 0 | G6: =IF(E6-D6>0,E6-D6,0) -> 47784
A7: 173000 | B7: Schulden aan kredietinstellingen | C7: Passief | D7: =SUMIF('1. Journaal'!$C$4:$C$186,$A7,'1. Journaal'!$E$4:$E$186) -> 37500 | E7: =SUMIF('1. Journaal'!$C$4:$C$186,$A7,'1. Journaal'!$F$4:$F$186) -> 150000 | F7: =IF(D7-E7>0,D7-E7,0) -> 0 | G7: =IF(E7-D7>0,E7-D7,0) -> 112500
A8: 221000 | B8: Gebouwen | C8: Actief | D8: =SUMIF('1. Journaal'!$C$4:$C$186,$A8,'1. Journaal'!$E$4:$E$186) -> 400000 | E8: =SUMIF('1. Journaal'!$C$4:$C$186,$A8,'1. Journaal'!$F$4:$F$186) -> 0 | F8: =IF(D8-E8>0,D8-E8,0) -> 400000 | G8: =IF(E8-D8>0,E8-D8,0) -> 0
A9: 221009 | B9: Afschrijvingen op gebouwen (-) | C9: Actief (min) | D9: =SUMIF('1. Journaal'!$C$4:$C$186,$A9,'1. Journaal'!$E$4:$E$186) -> 0 | E9: =SUMIF('1. Journaal'!$C$4:$C$186,$A9,'1. Journaal'!$F$4:$F$186) -> 165000 | F9: =IF(D9-E9>0,D9-E9,0) -> 0 | G9: =IF(E9-D9>0,E9-D9,0) -> 165000
A10: 230000 | B10: Installaties | C10: Actief | D10: =SUMIF('1. Journaal'!$C$4:$C$186,$A10,'1. Journaal'!$E$4:$E$186) -> 100000 | E10: =SUMIF('1. Journaal'!$C$4:$C$186,$A10,'1. Journaal'!$F$4:$F$186) -> 0 | F10: =IF(D10-E10>0,D10-E10,0) -> 100000 | G10: =IF(E10-D10>0,E10-D10,0) -> 0
A11: 230009 | B11: Afschrijvingen op installaties (-) | C11: Actief (min) | D11: =SUMIF('1. Journaal'!$C$4:$C$186,$A11,'1. Journaal'!$E$4:$E$186) -> 0 | E11: =SUMIF('1. Journaal'!$C$4:$C$186,$A11,'1. Journaal'!$F$4:$F$186) -> 72500 | F11: =IF(D11-E11>0,D11-E11,0) -> 0 | G11: =IF(E11-D11>0,E11-D11,0) -> 72500
A12: 240000 | B12: Meubilair | C12: Actief | D12: =SUMIF('1. Journaal'!$C$4:$C$186,$A12,'1. Journaal'!$E$4:$E$186) -> 60000 | E12: =SUMIF('1. Journaal'!$C$4:$C$186,$A12,'1. Journaal'!$F$4:$F$186) -> 0 | F12: =IF(D12-E12>0,D12-E12,0) -> 60000 | G12: =IF(E12-D12>0,E12-D12,0) -> 0
A13: 240009 | B13: Afschrijvingen op meubilair (-) | C13: Actief (min) | D13: =SUMIF('1. Journaal'!$C$4:$C$186,$A13,'1. Journaal'!$E$4:$E$186) -> 0 | E13: =SUMIF('1. Journaal'!$C$4:$C$186,$A13,'1. Journaal'!$F$4:$F$186) -> 31500 | F13: =IF(D13-E13>0,D13-E13,0) -> 0 | G13: =IF(E13-D13>0,E13-D13,0) -> 31500
A14: 241000 | B14: Rollend materieel | C14: Actief | D14: =SUMIF('1. Journaal'!$C$4:$C$186,$A14,'1. Journaal'!$E$4:$E$186) -> 90000 | E14: =SUMIF('1. Journaal'!$C$4:$C$186,$A14,'1. Journaal'!$F$4:$F$186) -> 0 | F14: =IF(D14-E14>0,D14-E14,0) -> 90000 | G14: =IF(E14-D14>0,E14-D14,0) -> 0
A15: 241009 | B15: Afschrijvingen op rollend materieel (-) | C15: Actief (min) | D15: =SUMIF('1. Journaal'!$C$4:$C$186,$A15,'1. Journaal'!$E$4:$E$186) -> 0 | E15: =SUMIF('1. Journaal'!$C$4:$C$186,$A15,'1. Journaal'!$F$4:$F$186) -> 44500 | F15: =IF(D15-E15>0,D15-E15,0) -> 0 | G15: =IF(E15-D15>0,E15-D15,0) -> 44500
... A56: 757000 | B56: Betalingskortingen van leveranciers | C56: Opbrengst | D56: =SUMIF('1. Journaal'!$C$4:$C$186,$A56,'1. Journaal'!$E$4:$E$186) -> 0 | E56: =SUMIF('1. Journaal'!$C$4:$C$186,$A56,'1. Journaal'!$F$4:$F$186) -> 600 | F56: =IF(D56-E56>0,D56-E56,0) -> 0 | G56: =IF(E56-D56>0,E56-D56,0) -> 600
B57: TOTAAL | D57: =SUM(D4:D56) -> 2184714 | E57: =SUM(E4:E56) -> 2184714 | F57: =SUM(F4:F56) -> 1135040 | G57: =SUM(G4:G56) -> 1135040

Sheet 3. Resultatenrekening
A1: Resultatenrekening 1 januari - 31 maart 2026
A3: Rekening | B3: Naam rekening | C3: Kosten | D3: Opbrengsten
A4: 604000 | B4: Aankopen handelsgoederen | C4: ='2. Proef- en saldibalans'!F35-'2. Proef- en saldibalans'!G35 -> 130000
A5: 604010 | B5: Retours op aankopen (-) | C5: ='2. Proef- en saldibalans'!F36-'2. Proef- en saldibalans'!G36 -> -2000
A6: 604020 | B6: Handelskorting op aankopen (-) | C6: ='2. Proef- en saldibalans'!F37-'2. Proef- en saldibalans'!G37 -> -3900
A7: 604030 | B7: Aankoopkosten | C7: ='2. Proef- en saldibalans'!F38-'2. Proef- en saldibalans'!G38 -> 400
A8: 609400 | B8: Voorraadwijzigingen handelsgoederen | C8: ='2. Proef- en saldibalans'!F39-'2. Proef- en saldibalans'!G39 -> -10000
A9: 612600 | B9: Verbruik gas | C9: ='2. Proef- en saldibalans'!F40-'2. Proef- en saldibalans'!G40 -> 500
A10: 612700 | B10: Verbruik elektriciteit | C10: ='2. Proef- en saldibalans'!F41-'2. Proef- en saldibalans'!G41 -> 1500
A11: 613300 | B11: Sociaal secretariaat | C11: ='2. Proef- en saldibalans'!F42-'2. Proef- en saldibalans'!G42 -> 400
A12: 620200 | B12: Bezoldigingen bedienden | C12: ='2. Proef- en saldibalans'!F43-'2. Proef- en saldibalans'!G43 -> 20000
A13: 620300 | B13: Bezoldigingen arbeiders | C13: ='2. Proef- en saldibalans'!F44-'2. Proef- en saldibalans'!G44 -> 10000
A14: 621000 | B14: Werkgeversbijdrage RSZ | C14: ='2. Proef- en saldibalans'!F45-'2. Proef- en saldibalans'!G45 -> 7500
A15: 630200 | B15: Afschrijvingen op materiële vaste activa | C15: ='2. Proef- en saldibalans'!F46-'2. Proef- en saldibalans'!G46 -> 7500
... A18: 657000 | B18: Betalingskortingen aan klanten | C18: ='2. Proef- en saldibalans'!F49-'2. Proef- en saldibalans'!G49 -> 800
A19: 704000 | B19: Verkopen handelsgoederen | D19: ='2. Proef- en saldibalans'!G52-'2. Proef- en saldibalans'!F52 -> 187000
A20: 704010 | B20: Retours op verkopen (-) | D20: ='2. Proef- en saldibalans'!G53-'2. Proef- en saldibalans'!F53 -> -4000
A21: 704020 | B21: Handelskorting op verkopen (-) | D21: ='2. Proef- en saldibalans'!G54-'2. Proef- en saldibalans'!F54 -> -4400
A22: 746000 | B22: Doorgerekende kosten | D22: ='2. Proef- en saldibalans'!G55-'2. Proef- en saldibalans'!F55 -> 1000
A23: 757000 | B23: Betalingskortingen van leveranciers | D23: ='2. Proef- en saldibalans'!G56-'2. Proef- en saldibalans'!F56 -> 600
B25: Totaal kosten (klasse 6) | C25: =SUM(C4:C18) -> 170470 | D25: =SUM(D19:D23) -> 180200
B26: Totaal opbrengsten (klasse 7)
B27: Winst voor belasting | C27: =D25-C25 -> 9730
A28: 670200 | B28: Geraamde belastingen (20%) | C28: ='2. Proef- en saldibalans'!F50-'2. Proef- en saldibalans'!G50 -> 1946
B29: Winst na belasting | C29: =C27-C28 -> 7784
A31: 693000 | B31: Over te dragen winst | C31: ='2. Proef- en saldibalans'!F51-'2. Proef- en saldibalans'!G51 -> 7784

Sheet 4. Eindbalans
A1: Balans 31 maart 2026
A3: Rekening | B3: Naam rekening | C3: Actief | D3: Passief
A4: 100000 | B4: Geplaatst kapitaal | D4: ='2. Proef- en saldibalans'!G4-'2. Proef- en saldibalans'!F4 -> 350000
A5: 130000 | B5: Wettelijke reserve | D5: ='2. Proef- en saldibalans'!G5-'2. Proef- en saldibalans'!F5 -> 50000
A6: 140000 | B6: Overgedragen winst | D6: ='2. Proef- en saldibalans'!G6-'2. Proef- en saldibalans'!F6 -> 47784
A7: 173000 | B7: Schulden aan kredietinstellingen | D7: ='2. Proef- en saldibalans'!G7-'2. Proef- en saldibalans'!F7 -> 112500
A8: 221000 | B8: Gebouwen | C8: ='2. Proef- en saldibalans'!F8-'2. Proef- en saldibalans'!G8 -> 400000
A9: 221009 | B9: Afschrijvingen op gebouwen (-) | C9: ='2. Proef- en saldibalans'!F9-'2. Proef- en saldibalans'!G9 -> -165000
A10: 230000 | B10: Installaties | C10: ='2. Proef- en saldibalans'!F10-'2. Proef- en saldibalans'!G10 -> 100000
A11: 230009 | B11: Afschrijvingen op installaties (-) | C11: ='2. Proef- en saldibalans'!F11-'2. Proef- en saldibalans'!G11 -> -72500
A12: 240000 | B12: Meubilair | C12: ='2. Proef- en saldibalans'!F12-'2. Proef- en saldibalans'!G12 -> 60000
A13: 240009 | B13: Afschrijvingen op meubilair (-) | C13: ='2. Proef- en saldibalans'!F13-'2. Proef- en saldibalans'!G13 -> -31500
A14: 241000 | B14: Rollend materieel | C14: ='2. Proef- en saldibalans'!F14-'2. Proef- en saldibalans'!G14 -> 90000
A15: 241009 | B15: Afschrijvingen op rollend materieel (-) | C15: ='2. Proef- en saldibalans'!F15-'2. Proef- en saldibalans'!G15 -> -44500
A16: 340000 | B16: Voorraad handelsgoederen | C16: ='2. Proef- en saldibalans'!F16-'2. Proef- en saldibalans'!G16 -> 110000
A17: 400000 | B17: Handelsdebiteuren | C17: ='2. Proef- en saldibalans'!F17-'2. Proef- en saldibalans'!G17 -> 22264
A18: 411100 | B18: Aftrekbare btw | C18: ='2. Proef- en saldibalans'!F18-'2. Proef- en saldibalans'!G18 -> 0
A19: 411200 | B19: Aftrekbare btw op uitgaande creditnota’s | C19: ='2. Proef- en saldibalans'!F19-'2. Proef- en saldibalans'!G19 -> 0
A20: 418000 | B20: Terug te vorderen verpakking | C20: ='2. Proef- en saldibalans'!F20-'2. Proef- en saldibalans'!G20 -> 400
A21: 423000 | B21: Binnen het jaar vervallende schulden aan kredietinstellingen | D21: ='2. Proef- en saldibalans'!G21-'2. Proef- en saldibalans'!F21 -> 30000
A22: 440000 | B22: Leveranciers | D22: ='2. Proef- en saldibalans'!G22-'2. Proef- en saldibalans'!F22 -> 21091
A23: 450000 | B23: Geraamd bedrag der Belgische winstbelastingen | D23: ='2. Proef- en saldibalans'!G23-'2. Proef- en saldibalans'!F23 -> 1946
A24: 451000 | B24: Te betalen btw-saldo | D24: ='2. Proef- en saldibalans'!G24-'2. Proef- en saldibalans'!F24 -> 3219
A25: 451100 | B25: Verschuldigde btw | D25: ='2. Proef- en saldibalans'!G25-'2. Proef- en saldibalans'!F25 -> 0
A26: 451200 | B26: Verschuldigde btw op inkomende creditnota’s | D26: ='2. Proef- en saldibalans'!G26-'2. Proef- en saldibalans'!F26 -> 0
A27: 453000 | B27: Ingehouden bedrijfsvoorheffing | D27: ='2. Proef- en saldibalans'!G27-'2. Proef- en saldibalans'!F27 -> 0
A28: 454000 | B28: Rijksdienst voor Sociale Zekerheid (RSZ) | D28: ='2. Proef- en saldibalans'!G28-'2. Proef- en saldibalans'!F28 -> 0
A29: 455200 | B29: Verschuldigde lonen bedienden | D29: ='2. Proef- en saldibalans'!G29-'2. Proef- en saldibalans'!F29 -> 0
A30: 455300 | B30: Verschuldigde lonen arbeiders | D30: ='2. Proef- en saldibalans'!G30-'2. Proef- en saldibalans'!F30 -> 0
A31: 488000 | B31: Terug te betalen verpakking | D31: ='2. Proef- en saldibalans'!G31-'2. Proef- en saldibalans'!F31 -> 500
A32: 550000 | B32: Bankrekening | C32: ='2. Proef- en saldibalans'!F32-'2. Proef- en saldibalans'!G32 -> 146676
A33: 570000 | B33: Kas | C33: ='2. Proef- en saldibalans'!F33-'2. Proef- en saldibalans'!G33 -> 1200
A34: 580000 | B34: Interne overboekingen | C34: ='2. Proef- en saldibalans'!F34-'2. Proef- en saldibalans'!G34 -> 0
B35: TOTAAL | C35: =SUM(C4:C34) -> 617040 | D35: =SUM(D4:D34) -> 617040

Sheet 5. Documenten
A1: Overzicht van de 43 documenten
A3: Bestandsnaam | B3: Soort | C3: Nummer op document | D3: Datum | E3: Tegenpartij / omschrijving | F3: Totaalbedrag | G3: Bijzonderheid
A4: BEGINBALANS | B4: Beginbalans | C4: - | D4: 46023 | E4: MetWear bv | G4: balans op 1 januari 2026
A5: BEGINSALDI | B5: Beginsaldi | C5: - | D5: 46023 | E5: MetWear bv | F5: 842000 | G5: overzicht van alle rekeningen
A6: VK01 | B6: Verkoopfactuur | C6: 2026-01 | D6: 46025 | E6: Concept Store Nova bv | F6: 26136 | G6: handelskorting 10%
A7: VK02 | B7: Verkoopfactuur | C7: 2026-02 | D7: 46032 | E7: Kringwinkel De Draad vzw | F7: 24960 | G7: gemengd 21% en 6%
A8: VK03 | B8: Verkoopfactuur | C8: 2026-03 | D8: 46039 | E8: Modehuis Vandeputte bv | F8: 37526 | G8: vervoerskosten, verpakking (waarborg)
A9: VK04 | B9: Creditnota verkoop | C9: 2026-04 | D9: 46057 | E9: Modehuis Vandeputte bv | F9: 500 | G9: op factuur 2026-03 - verpakking terug
A10: VK05 | B10: Verkoopfactuur | C10: 2026-05 | D10: 46061 | E10: Boetiek Lumen bv | F10: 47432 | G10: financiele korting 2%
A11: VK06 | B11: Verkoopfactuur | C11: 2026-06 | D11: 46075 | E11: Sportclub De Kern vzw | F11: 22264 | G11: handelskorting, vervoerskosten
A12: VK07 | B12: Verkoopfactuur | C12: 2026-07 | D12: 46093 | E12: Concept Store Nova bv | F12: 36500 | G12: gemengd 21% en 6%, verpakking (waarborg)
A13: VK08 | B13: Creditnota verkoop | C13: 2026-08 | D13: 46105 | E13: Concept Store Nova bv | F13: 4840 | G13: op factuur 2026-07 - goederen terug
A14: AK01 | B14: Aankoopfactuur | C14: TX-2026/418 | D14: 46024 | E14: Textura nv | F14: 24200 | G14: -
A15: AK02 | B15: Aankoopfactuur | C15: 2026/0912 | D15: 46031 | E15: Groene Draad bvba | F15: 32670 | G15: handelskorting 10%
A16: AK03 | B16: Aankoopfactuur | C16: BCB-4471 | D16: 46043 | E16: Bio Cotton Belgium bv | F16: 30124 | G16: vervoerskosten, verpakking (waarborg)
... A27: LOON | B27: Loonstaat | C27: - | D27: 46081 | E27: SoLoon vzw | F27: 37500 | G27: totale loonkost februari 2026
A28: BANK01 | B28: Bankuittreksel | C28: 2026/01 | D28: 46024 | E28: NovaBank | G28: kredietopname lening, ontvangst klanten 2025
A29: BANK02 | B29: Bankuittreksel | C29: 2026/02 | D29: 46025 | E29: NovaBank | G29: betaling leveranciers 2025, nettolonen december
A30: BANK03 | B30: Bankuittreksel | C30: 2026/03 | D30: 46029 | E30: NovaBank | G30: betaling TX-2026/418, btw
A31: BANK05 | B31: Bankuittreksel | C31: 2026/05 | D31: 46042 | E31: NovaBank | G31: ontvangst 2026-01, betaling 2026/0912
A32: BANK06 | B32: Bankuittreksel | C32: 2026/06 | D32: 46053 | E32: NovaBank | G32: bankkaartontvangsten, 1e aflossing lening
A33: BANK07 | B33: Bankuittreksel | C33: 2026/07 | D33: 46059 | E33: NovaBank | G33: betaling onder aftrek creditnota, storting kas
A34: BANK08 | B34: Bankuittreksel | C34: 2026/08 | D34: 46071 | E34: NovaBank | G34: ontvangst onder aftrek creditnota
A35: BANK09 | B35: Bankuittreksel | C35: 2026/09 | D35: 46081 | E35: NovaBank | G35: nettolonen februari, 2e aflossing lening
A36: BANK10 | B36: Bankuittreksel | C36: 2026/10 | D36: 46083 | E36: NovaBank | G36: betaling NE-2026-5502
A37: BANK11 | B37: Bankuittreksel | C37: 2026/11 | D37: 46093 | E37: NovaBank | G37: betaling GD-2026/188, SL-0631, SL-0632
A38: BANK12 | B38: Bankuittreksel | C38: 2026/12 | D38: 46096 | E38: NovaBank | G38: betaling 2026-037
A39: BANK13 | B39: Bankuittreksel | C39: 2026/13 | D39: 46107 | E39: NovaBank | G39: ontvangst factuur 2026-07 onder aftrek creditnota 2026-08
... A43: LENING2 | B43: Aflossingstabel p.2 | C43: 2026/4471 | D43: 46052 | E43: NovaBank | G43: per jaar 2026-2030 - nodig bij de overboeking LT naar KT
A44: AFSCHR1 | B44: Afschrijvingstabel | C44: AFSCHR1 | D44: 46112 | E44: MetWear bv | F44: 13500 | G44: afschrijving 1e kwartaal, pro rata 3/12
A45: VR | B45: Voorraadtelling | C45: VR | D45: 46112 | E45: MetWear bv | F45: 110000 | G45: eindvoorraad handelsgoederen

Sheet 6. Controles
A1: Controles - elke uitkomst moet 0 zijn
A3: Controle | B3: Uitkomst
A4: Journaal: totaal debet - totaal credit | B4: ='1. Journaal'!E188-'1. Journaal'!F188 -> 0
A5: Proefbalans: debettotalen - credittotalen | B5: ='2. Proef- en saldibalans'!D57-'2. Proef- en saldibalans'!E57 -> 0
A6: Saldibalans: debetsaldi - creditsaldi | B6: ='2. Proef- en saldibalans'!F57-'2. Proef- en saldibalans'!G57 -> 0
A7: Balans: actief - passief | B7: ='4. Eindbalans'!C35-'4. Eindbalans'!D35 -> 0
A8: Winst na belasting - toevoeging aan overgedragen winst (693000) | B8: ='3. Resultatenrekening'!C29-'3. Resultatenrekening'!C31 -> 0
A9: Banksaldo 550000 - eindsaldo BANK14 (146.676) | B9: ='2. Proef- en saldibalans'!F32-146676 -> 0
A10: Kassaldo 570000 - eindsaldo KAS01 (1.200) | B10: ='2. Proef- en saldibalans'!F33-1200 -> 0
A11: Voorraad 340000 - voorraadtelling VR (110.000) | B11: ='2. Proef- en saldibalans'!F16-110000 -> 0
A12: Interne overboekingen 580000 (moet leeg zijn) | B12: ='2. Proef- en saldibalans'!D34-'2. Proef- en saldibalans'!E34 -> 0
A13: Tussentijdse btw-rekeningen 411100 / 411200 / 451100 / 451200 (moeten leeg zijn) | B13: ='2. Proef- en saldibalans'!F18+'2. Proef- en saldibalans'!G18+'2. Proef- en saldibalans'!F19+'2. Proef- en saldibalans'!G19+'2. Proef- en saldibalans'!F25+'2. Proef- en saldibalans'!G25+'2. Proef- en saldibalans'!F26+'2. Proef- en saldibalans'!G26 -> 0
A14: Verschuldigde lonen 455200 + 455300 na uitbetaling (moeten leeg zijn) | B14: ='2. Proef- en saldibalans'!F29+'2. Proef- en saldibalans'!G29+'2. Proef- en saldibalans'!F30+'2. Proef- en saldibalans'!G30 -> 0
A15: Lening: 173000 + 423000 - openstaand kapitaal 31/03 (142.500) | B15: ='2. Proef- en saldibalans'!G7+'2. Proef- en saldibalans'!G21-142500 -> 0
A16: Openstaand bij leveranciers 440000 - AK07 min creditnota AK08 (21.091) | B16: ='2. Proef- en saldibalans'!G22-21091 -> 0
A17: Openstaand bij klanten 400000 - VK06 Sportclub De Kern (22.264) | B17: ='2. Proef- en saldibalans'!F17-22264 -> 0

Sheet 7. Aflossingstabel
A1: Lening 2026/4471 - NovaBank
A3: kapitaal | B3: 150000
A4: jaarlijkse rentevoet | B4: 0.048
A5: aflossing kapitaal per maand | B5: 2500
A7: MND | B7: VERVALDAG | C7: JAAR | D7: OPENSTAANDE SCHULD | E7: AF TE LOSSEN KAPITAAL | F7: TE BETALEN INTEREST | G7: MAANDLAST | H7: NOG VERSCHULDIGD KAPITAAL | J7: JAAR | K7: AFLOSSING KAPITAAL | L7: BETAALDE INTEREST | M7: NOG VERSCHULDIGD KAPITAAL
A8: 1 | B8: 46053 | C8: =YEAR(B8) -> 2026 | D8: =$B$3 -> 150000 | E8: =$B$5 -> 2500 | F8: =D8*$B$4/12 -> 600 | G8: =E8+F8 -> 3100 | H8: =D8-E8 -> 147500 | J8: 2026 | K8: =SUMIF($C$8:$C$67,$J8,$E$8:$E$67) -> 30000 | L8: =SUMIF($C$8:$C$67,$J8,$F$8:$F$67) -> 6540 | M8: =IF(J8=2026,$B$3-K8,M7-K8) -> 120000
A9: 2 | B9: =EOMONTH(B8,1) -> 46081 | C9: =YEAR(B9) -> 2026 | D9: =H8 -> 147500 | E9: =$B$5 -> 2500 | F9: =D9*$B$4/12 -> 590 | G9: =E9+F9 -> 3090 | H9: =D9-E9 -> 145000 | J9: 2027 | K9: =SUMIF($C$8:$C$67,$J9,$E$8:$E$67) -> 30000 | L9: =SUMIF($C$8:$C$67,$J9,$F$8:$F$67) -> 5100 | M9: =IF(J9=2026,$B$3-K9,M8-K9) -> 90000
A10: 3 | B10: =EOMONTH(B9,1) -> 46112 | C10: =YEAR(B10) -> 2026 | D10: =H9 -> 145000 | E10: =$B$5 -> 2500 | F10: =D10*$B$4/12 -> 580 | G10: =E10+F10 -> 3080 | H10: =D10-E10 -> 142500 | J10: 2028 | K10: =SUMIF($C$8:$C$67,$J10,$E$8:$E$67) -> 30000 | L10: =SUMIF($C$8:$C$67,$J10,$F$8:$F$67) -> 3660 | M10: =IF(J10=2026,$B$3-K10,M9-K10) -> 60000
A11: 4 | B11: =EOMONTH(B10,1) -> 46142 | C11: =YEAR(B11) -> 2026 | D11: =H10 -> 142500 | E11: =$B$5 -> 2500 | F11: =D11*$B$4/12 -> 570 | G11: =E11+F11 -> 3070 | H11: =D11-E11 -> 140000 | J11: 2029 | K11: =SUMIF($C$8:$C$67,$J11,$E$8:$E$67) -> 30000 | L11: =SUMIF($C$8:$C$67,$J11,$F$8:$F$67) -> 2220 | M11: =IF(J11=2026,$B$3-K11,M10-K11) -> 30000
A12: 5 | B12: =EOMONTH(B11,1) -> 46173 | C12: =YEAR(B12) -> 2026 | D12: =H11 -> 140000 | E12: =$B$5 -> 2500 | F12: =D12*$B$4/12 -> 560 | G12: =E12+F12 -> 3060 | H12: =D12-E12 -> 137500 | J12: 2030 | K12: =SUMIF($C$8:$C$67,$J12,$E$8:$E$67) -> 30000 | L12: =SUMIF($C$8:$C$67,$J12,$F$8:$F$67) -> 780 | M12: =IF(J12=2026,$B$3-K12,M11-K12) -> 0
A13: 6 | B13: =EOMONTH(B12,1) -> 46203 | C13: =YEAR(B13) -> 2026 | D13: =H12 -> 137500 | E13: =$B$5 -> 2500 | F13: =D13*$B$4/12 -> 550 | G13: =E13+F13 -> 3050 | H13: =D13-E13 -> 135000
A14: 7 | B14: =EOMONTH(B13,1) -> 46234 | C14: =YEAR(B14) -> 2026 | D14: =H13 -> 135000 | E14: =$B$5 -> 2500 | F14: =D14*$B$4/12 -> 540 | G14: =E14+F14 -> 3040 | H14: =D14-E14 -> 132500 | J14: Overboeking lange naar korte termijn op 31/03/2026
A15: 8 | B15: =EOMONTH(B14,1) -> 46265 | C15: =YEAR(B15) -> 2026 | D15: =H14 -> 132500 | E15: =$B$5 -> 2500 | F15: =D15*$B$4/12 -> 530 | G15: =E15+F15 -> 3030 | H15: =D15-E15 -> 130000 | J15: 12 maandaflossingen die vervallen tussen 01/04/2026 en 31/03/2027
A16: 9 | B16: =EOMONTH(B15,1) -> 46295 | C16: =YEAR(B16) -> 2026 | D16: =H15 -> 130000 | E16: =$B$5 -> 2500 | F16: =D16*$B$4/12 -> 520 | G16: =E16+F16 -> 3020 | H16: =D16-E16 -> 127500 | J16: =12*$B$5 -> 30000
A17: 10 | B17: =EOMONTH(B16,1) -> 46326 | C17: =YEAR(B17) -> 2026 | D17: =H16 -> 127500 | E17: =$B$5 -> 2500 | F17: =D17*$B$4/12 -> 510 | G17: =E17+F17 -> 3010 | H17: =D17-E17 -> 125000
A18: 11 | B18: =EOMONTH(B17,1) -> 46356 | C18: =YEAR(B18) -> 2026 | D18: =H17 -> 125000 | E18: =$B$5 -> 2500 | F18: =D18*$B$4/12 -> 500 | G18: =E18+F18 -> 3000 | H18: =D18-E18 -> 122500
A19: 12 | B19: =EOMONTH(B18,1) -> 46387 | C19: =YEAR(B19) -> 2026 | D19: =H18 -> 122500 | E19: =$B$5 -> 2500 | F19: =D19*$B$4/12 -> 490 | G19: =E19+F19 -> 2990 | H19: =D19-E19 -> 120000
A20: 13 | B20: =EOMONTH(B19,1) -> 46418 | C20: =YEAR(B20) -> 2027 | D20: =H19 -> 120000 | E20: =$B$5 -> 2500 | F20: =D20*$B$4/12 -> 480 | G20: =E20+F20 -> 2980 | H20: =D20-E20 -> 117500
A21: 14 | B21: =EOMONTH(B20,1) -> 46446 | C21: =YEAR(B21) -> 2027 | D21: =H20 -> 117500 | E21: =$B$5 -> 2500 | F21: =D21*$B$4/12 -> 470 | G21: =E21+F21 -> 2970 | H21: =D21-E21 -> 115000
A22: 15 | B22: =EOMONTH(B21,1) -> 46477 | C22: =YEAR(B22) -> 2027 | D22: =H21 -> 115000 | E22: =$B$5 -> 2500 | F22: =D22*$B$4/12 -> 460 | G22: =E22+F22 -> 2960 | H22: =D22-E22 -> 112500
A23: 16 | B23: =EOMONTH(B22,1) -> 46507 | C23: =YEAR(B23) -> 2027 | D23: =H22 -> 112500 | E23: =$B$5 -> 2500 | F23: =D23*$B$4/12 -> 450 | G23: =E23+F23 -> 2950 | H23: =D23-E23 -> 110000
A24: 17 | B24: =EOMONTH(B23,1) -> 46538 | C24: =YEAR(B24) -> 2027 | D24: =H23 -> 110000 | E24: =$B$5 -> 2500 | F24: =D24*$B$4/12 -> 440 | G24: =E24+F24 -> 2940 | H24: =D24-E24 -> 107500
A25: 18 | B25: =EOMONTH(B24,1) -> 46568 | C25: =YEAR(B25) -> 2027 | D25: =H24 -> 107500 | E25: =$B$5 -> 2500 | F25: =D25*$B$4/12 -> 430 | G25: =E25+F25 -> 2930 | H25: =D25-E25 -> 105000
A26: 19 | B26: =EOMONTH(B25,1) -> 46599 | C26: =YEAR(B26) -> 2027 | D26: =H25 -> 105000 | E26: =$B$5 -> 2500 | F26: =D26*$B$4/12 -> 420 | G26: =E26+F26 -> 2920 | H26: =D26-E26 -> 102500
A27: 20 | B27: =EOMONTH(B26,1) -> 46630 | C27: =YEAR(B27) -> 2027 | D27: =H26 -> 102500 | E27: =$B$5 -> 2500 | F27: =D27*$B$4/12 -> 410 | G27: =E27+F27 -> 2910 | H27: =D27-E27 -> 100000
A28: 21 | B28: =EOMONTH(B27,1) -> 46660 | C28: =YEAR(B28) -> 2027 | D28: =H27 -> 100000 | E28: =$B$5 -> 2500 | F28: =D28*$B$4/12 -> 400 | G28: =E28+F28 -> 2900 | H28: =D28-E28 -> 97500
... A67: 60 | B67: =EOMONTH(B66,1) -> 47848 | C67: =YEAR(B67) -> 2030 | D67: =H66 -> 2500 | E67: =$B$5 -> 2500 | F67: =D67*$B$4/12 -> 10 | G67: =E67+F67 -> 2510 | H67: =D67-E67 -> 0
