Workbook

Sheet Leeswijzer
A1: Case Fietsatelier Noor bv: gegevens voor de boekhoudapp 3e en 4e jaar
A2: Wat staat hierin? | B2: Alle gegevens van de case: bedrijven, artikelen, documenten (met lijnen), rekeninguittreksels en de sleutel (journaal). Facturen maak je zelf op basis van de tabbladen Documenten en Lijnen.
A3: Jaar 1 = 2026 (3e jaar) | B3: Eerste jaar na de opstart. Januari = voorbeelden uit de cursus. Kwartaal 1 = verplichte opdrachten (in blok). Kwartaal 2 = oefenen, kwartaal 3 = test jezelf, kwartaal 4 = remediëring (telkens alles door elkaar). Eind december: 2 facturen en de afsluiting door de boekhouder (niet voor leerlingen).
A4: Jaar 2 = 2027 (4e jaar) | B4: Consolidatieopdracht: iedereen doet alle kwartalen. Start vanuit een volledig afgewerkt jaar 1 (openingsbalans 1/1/2027 = eindbalans 2026 na afsluiting). Per kwartaal meer gemixt: K1 in blok per soort · K2 gemixt binnen aankoop en binnen verkoop · K3 aankoop en verkoop door elkaar · K4 alles door elkaar. Daarna de afsluiting. '(eventueel enkel tot kwartaal 3, en K4 houden voor remediëring)
A5: Jaar 3 = 2028 (3e graad, oefenen) | B5: Oefendossier in de boekhoudapp van kern 8 (noor.html): het 1e kwartaal 2028 met een afsluiting op 31 maart, zoals MetWear. Beginbalans = eindbalans 2027 na afsluiting. Noor heeft nu personeel (Jonas, arbeider; Lina, bediende deeltijds), een sociaal secretariaat (Loonwijs), een verzekeraar (Gerzo) en een opslagruimte (Immo Vaartkom). De stukken staan per les (5 à 6 per les): kortingen · kosten, verpakking, investeringen · creditnota's en over te dragen kosten · verkopen (2 lessen) · loonstaten · RSZ en personeelskosten · financiële verrichtingen · btw, eindejaar en resultaat. Tabbladen J3 …; gemaakt door hulpmiddelen/noor/ in de repo boekhouding_DeMet.
A6: Jaar 4 (3e graad, consolidatie) | B6: Nog te maken: alle stukken door elkaar, als eindopdracht (vanaf volgend schooljaar in de plaats van MetWear).
A7: Afspraken jaar 3 | B7: MAR van de 3e graad (js/mar.js) plus 700000 voor herstellingen. Over te dragen kosten: de factuur volledig als kost, bij de afsluiting het deel na 31/3 naar 490000 (OTK). Lonen: RSZ werknemer 13,07%, werkgever 25%; RSZ en voorheffing via factuur van Loonwijs (440000). Afschrijvingen: een kwart van de jaarafschrijving. Lening: deel dat binnen 12 maanden vervalt naar 423000. Belasting 20%, wettelijke reserve 5% van de winst na belasting.
A8: Volgorde jaar 2 | B8: K1 tot K3: aankoop, verkoop, btw-verrekening, financieel (de volgorde van de cursus). K4: chronologisch.
A9: Kwartaal | B9: Een boekhoudperiode in de case, niet de periode in het schooljaar.
A10: Volgorde | B10: Kolom "Volgorde in set" in Documenten en Uittreksels: in die volgorde zet je de documenten open in de app.
A11: Formules | B11: Bedragen op de lijnen, totalen per document, saldi op de uittreksels, proefbalans en voorraad zijn formules. Pas je een aantal of prijs aan op Lijnen, dan rekenen de totalen mee. Het journaal (sleutel) is NIET gekoppeld: laat de case dan opnieuw genereren met het script.
A12: Controles | B12: Kolom "Controle D-C" in Documenten moet overal 0 zijn. Proefbalans: totaal = 0. Voorraad: waarde inventaris = saldo 340000 na afsluiting.
A13: Rekeningen | B13: MAR 2e graad (tabblad en bestand mar 2e graad.js): een selectie uit het MAR van de 3e graad, 6 cijfers, plus 600000 Aankopen grondstoffen en 700000 Verkopen en dienstprestaties. Btw op creditnota’s: 411200 (uitgaande CN) en 451200 (inkomende CN).
... A18: Fictief | B18: Alle bedrijven, adressen, btw-nummers (BE 0999...) en rekeningnummers (BE00...) zijn fictief.
A20: Kleur per set
A21: CURSUS
A22: VERPLICHT
A23: OEFEN
A24: TJ
A25: REMEDIERING
A26: BOEKHOUDER
A27: K1
A28: K2
A29: K3
A30: K4
A31: AFSLUITING

Sheet Overzicht sets
A1: Jaar | B1: Set | C1: AK | D1: CN-AK | E1: VK | F1: CN-VK | G1: DO | H1: KAS | I1: MEMO | J1: Uittreksels | K1: Gevraagd (AK / CN-AK / VK / CN-VK / DO)
A2: 1 | B2: CURSUS | C2: =COUNTIFS('J1 Documenten'!$C:$C,$B2,'J1 Documenten'!$E:$E,"AK") | D2: =COUNTIFS('J1 Documenten'!$C:$C,$B2,'J1 Documenten'!$E:$E,"CN-AK") | E2: =COUNTIFS('J1 Documenten'!$C:$C,$B2,'J1 Documenten'!$E:$E,"VK") | F2: =COUNTIFS('J1 Documenten'!$C:$C,$B2,'J1 Documenten'!$E:$E,"CN-VK") | G2: =COUNTIFS('J1 Documenten'!$C:$C,$B2,'J1 Documenten'!$E:$E,"DO") | H2: =COUNTIFS('J1 Documenten'!$C:$C,$B2,'J1 Documenten'!$E:$E,"KAS") | I2: =COUNTIFS('J1 Documenten'!$C:$C,$B2,'J1 Documenten'!$E:$E,"MEMO") | J2: 3
A3: 1 | B3: VERPLICHT | C3: =COUNTIFS('J1 Documenten'!$C:$C,$B3,'J1 Documenten'!$E:$E,"AK") | D3: =COUNTIFS('J1 Documenten'!$C:$C,$B3,'J1 Documenten'!$E:$E,"CN-AK") | E3: =COUNTIFS('J1 Documenten'!$C:$C,$B3,'J1 Documenten'!$E:$E,"VK") | F3: =COUNTIFS('J1 Documenten'!$C:$C,$B3,'J1 Documenten'!$E:$E,"CN-VK") | G3: =COUNTIFS('J1 Documenten'!$C:$C,$B3,'J1 Documenten'!$E:$E,"DO") | H3: =COUNTIFS('J1 Documenten'!$C:$C,$B3,'J1 Documenten'!$E:$E,"KAS") | I3: =COUNTIFS('J1 Documenten'!$C:$C,$B3,'J1 Documenten'!$E:$E,"MEMO") | J3: 4 | K3: 5 / 3 / 5 / 3 / 3
A4: 1 | B4: OEFEN | C4: =COUNTIFS('J1 Documenten'!$C:$C,$B4,'J1 Documenten'!$E:$E,"AK") | D4: =COUNTIFS('J1 Documenten'!$C:$C,$B4,'J1 Documenten'!$E:$E,"CN-AK") | E4: =COUNTIFS('J1 Documenten'!$C:$C,$B4,'J1 Documenten'!$E:$E,"VK") | F4: =COUNTIFS('J1 Documenten'!$C:$C,$B4,'J1 Documenten'!$E:$E,"CN-VK") | G4: =COUNTIFS('J1 Documenten'!$C:$C,$B4,'J1 Documenten'!$E:$E,"DO") | H4: =COUNTIFS('J1 Documenten'!$C:$C,$B4,'J1 Documenten'!$E:$E,"KAS") | I4: =COUNTIFS('J1 Documenten'!$C:$C,$B4,'J1 Documenten'!$E:$E,"MEMO") | J4: 3 | K4: extra set samen: 10 / 5 / 10 / 5 / 2
A5: 1 | B5: TJ | C5: =COUNTIFS('J1 Documenten'!$C:$C,$B5,'J1 Documenten'!$E:$E,"AK") | D5: =COUNTIFS('J1 Documenten'!$C:$C,$B5,'J1 Documenten'!$E:$E,"CN-AK") | E5: =COUNTIFS('J1 Documenten'!$C:$C,$B5,'J1 Documenten'!$E:$E,"VK") | F5: =COUNTIFS('J1 Documenten'!$C:$C,$B5,'J1 Documenten'!$E:$E,"CN-VK") | G5: =COUNTIFS('J1 Documenten'!$C:$C,$B5,'J1 Documenten'!$E:$E,"DO") | H5: =COUNTIFS('J1 Documenten'!$C:$C,$B5,'J1 Documenten'!$E:$E,"KAS") | I5: =COUNTIFS('J1 Documenten'!$C:$C,$B5,'J1 Documenten'!$E:$E,"MEMO") | J5: 3 | K5: (verdeeld over oefenen, TJ en remediëring)
A6: 1 | B6: REMEDIERING | C6: =COUNTIFS('J1 Documenten'!$C:$C,$B6,'J1 Documenten'!$E:$E,"AK") | D6: =COUNTIFS('J1 Documenten'!$C:$C,$B6,'J1 Documenten'!$E:$E,"CN-AK") | E6: =COUNTIFS('J1 Documenten'!$C:$C,$B6,'J1 Documenten'!$E:$E,"VK") | F6: =COUNTIFS('J1 Documenten'!$C:$C,$B6,'J1 Documenten'!$E:$E,"CN-VK") | G6: =COUNTIFS('J1 Documenten'!$C:$C,$B6,'J1 Documenten'!$E:$E,"DO") | H6: =COUNTIFS('J1 Documenten'!$C:$C,$B6,'J1 Documenten'!$E:$E,"KAS") | I6: =COUNTIFS('J1 Documenten'!$C:$C,$B6,'J1 Documenten'!$E:$E,"MEMO") | J6: 4
A7: 1 | B7: BOEKHOUDER | C7: =COUNTIFS('J1 Documenten'!$C:$C,$B7,'J1 Documenten'!$E:$E,"AK") | D7: =COUNTIFS('J1 Documenten'!$C:$C,$B7,'J1 Documenten'!$E:$E,"CN-AK") | E7: =COUNTIFS('J1 Documenten'!$C:$C,$B7,'J1 Documenten'!$E:$E,"VK") | F7: =COUNTIFS('J1 Documenten'!$C:$C,$B7,'J1 Documenten'!$E:$E,"CN-VK") | G7: =COUNTIFS('J1 Documenten'!$C:$C,$B7,'J1 Documenten'!$E:$E,"DO") | H7: =COUNTIFS('J1 Documenten'!$C:$C,$B7,'J1 Documenten'!$E:$E,"KAS") | I7: =COUNTIFS('J1 Documenten'!$C:$C,$B7,'J1 Documenten'!$E:$E,"MEMO") | J7: 0
A9: 2 | B9: K1 | C9: =COUNTIFS('J2 Documenten'!$C:$C,$B9,'J2 Documenten'!$E:$E,"AK") | D9: =COUNTIFS('J2 Documenten'!$C:$C,$B9,'J2 Documenten'!$E:$E,"CN-AK") | E9: =COUNTIFS('J2 Documenten'!$C:$C,$B9,'J2 Documenten'!$E:$E,"VK") | F9: =COUNTIFS('J2 Documenten'!$C:$C,$B9,'J2 Documenten'!$E:$E,"CN-VK") | G9: =COUNTIFS('J2 Documenten'!$C:$C,$B9,'J2 Documenten'!$E:$E,"DO") | H9: =COUNTIFS('J2 Documenten'!$C:$C,$B9,'J2 Documenten'!$E:$E,"KAS") | I9: =COUNTIFS('J2 Documenten'!$C:$C,$B9,'J2 Documenten'!$E:$E,"MEMO") | J9: 8 | K9: in blok per soort
A10: 2 | B10: K2 | C10: =COUNTIFS('J2 Documenten'!$C:$C,$B10,'J2 Documenten'!$E:$E,"AK") | D10: =COUNTIFS('J2 Documenten'!$C:$C,$B10,'J2 Documenten'!$E:$E,"CN-AK") | E10: =COUNTIFS('J2 Documenten'!$C:$C,$B10,'J2 Documenten'!$E:$E,"VK") | F10: =COUNTIFS('J2 Documenten'!$C:$C,$B10,'J2 Documenten'!$E:$E,"CN-VK") | G10: =COUNTIFS('J2 Documenten'!$C:$C,$B10,'J2 Documenten'!$E:$E,"DO") | H10: =COUNTIFS('J2 Documenten'!$C:$C,$B10,'J2 Documenten'!$E:$E,"KAS") | I10: =COUNTIFS('J2 Documenten'!$C:$C,$B10,'J2 Documenten'!$E:$E,"MEMO") | J10: 5 | K10: gemixt binnen aankoop / verkoop
A11: 2 | B11: K3 | C11: =COUNTIFS('J2 Documenten'!$C:$C,$B11,'J2 Documenten'!$E:$E,"AK") | D11: =COUNTIFS('J2 Documenten'!$C:$C,$B11,'J2 Documenten'!$E:$E,"CN-AK") | E11: =COUNTIFS('J2 Documenten'!$C:$C,$B11,'J2 Documenten'!$E:$E,"VK") | F11: =COUNTIFS('J2 Documenten'!$C:$C,$B11,'J2 Documenten'!$E:$E,"CN-VK") | G11: =COUNTIFS('J2 Documenten'!$C:$C,$B11,'J2 Documenten'!$E:$E,"DO") | H11: =COUNTIFS('J2 Documenten'!$C:$C,$B11,'J2 Documenten'!$E:$E,"KAS") | I11: =COUNTIFS('J2 Documenten'!$C:$C,$B11,'J2 Documenten'!$E:$E,"MEMO") | J11: 5 | K11: aankoop en verkoop door elkaar
A12: 2 | B12: K4 | C12: =COUNTIFS('J2 Documenten'!$C:$C,$B12,'J2 Documenten'!$E:$E,"AK") | D12: =COUNTIFS('J2 Documenten'!$C:$C,$B12,'J2 Documenten'!$E:$E,"CN-AK") | E12: =COUNTIFS('J2 Documenten'!$C:$C,$B12,'J2 Documenten'!$E:$E,"VK") | F12: =COUNTIFS('J2 Documenten'!$C:$C,$B12,'J2 Documenten'!$E:$E,"CN-VK") | G12: =COUNTIFS('J2 Documenten'!$C:$C,$B12,'J2 Documenten'!$E:$E,"DO") | H12: =COUNTIFS('J2 Documenten'!$C:$C,$B12,'J2 Documenten'!$E:$E,"KAS") | I12: =COUNTIFS('J2 Documenten'!$C:$C,$B12,'J2 Documenten'!$E:$E,"MEMO") | J12: 5 | K12: alles door elkaar
A13: 2 | B13: AFSLUITING | C13: =COUNTIFS('J2 Documenten'!$C:$C,$B13,'J2 Documenten'!$E:$E,"AK") | D13: =COUNTIFS('J2 Documenten'!$C:$C,$B13,'J2 Documenten'!$E:$E,"CN-AK") | E13: =COUNTIFS('J2 Documenten'!$C:$C,$B13,'J2 Documenten'!$E:$E,"VK") | F13: =COUNTIFS('J2 Documenten'!$C:$C,$B13,'J2 Documenten'!$E:$E,"CN-VK") | G13: =COUNTIFS('J2 Documenten'!$C:$C,$B13,'J2 Documenten'!$E:$E,"DO") | H13: =COUNTIFS('J2 Documenten'!$C:$C,$B13,'J2 Documenten'!$E:$E,"KAS") | I13: =COUNTIFS('J2 Documenten'!$C:$C,$B13,'J2 Documenten'!$E:$E,"MEMO") | J13: 0
A14: 3 | B14: Aankopen 1 · kortingen | C14: 6 | D14: 0 | E14: 0 | F14: 0 | G14: 0 | H14: 0 | I14: 0 | J14: 0
A15: 3 | B15: Aankopen 2 · kosten, verpakking en investeringen | C15: 6 | D15: 0 | E15: 0 | F15: 0 | G15: 0 | H15: 0 | I15: 0 | J15: 0
A16: 3 | B16: Aankopen 3 · creditnota's en over te dragen kosten | C16: 2 | D16: 3 | E16: 0 | F16: 0 | G16: 0 | H16: 0 | I16: 0 | J16: 0
A17: 3 | B17: Verkopen 1 · handelskorting en kosten | C17: 0 | D17: 0 | E17: 6 | F17: 0 | G17: 0 | H17: 0 | I17: 0 | J17: 0
A18: 3 | B18: Verkopen 2 · verpakking, creditnota's, financiële korting | C18: 0 | D18: 0 | E18: 3 | F18: 2 | G18: 1 | H18: 0 | I18: 0 | J18: 0
A19: 3 | B19: Lonen 1 · loonstaten | C19: 0 | D19: 0 | E19: 0 | F19: 0 | G19: 0 | H19: 0 | I19: 0 | J19: 0 | K19: loonstaten: 6
A20: 3 | B20: Lonen 2 · RSZ, voorheffing en personeelskosten | C20: 6 | D20: 0 | E20: 0 | F20: 0 | G20: 0 | H20: 0 | I20: 0 | J20: 0
A21: 3 | B21: Financiële verrichtingen | C21: 0 | D21: 0 | E21: 0 | F21: 0 | G21: 0 | H21: 2 | I21: 0 | J21: 5
A22: 3 | B22: BTW-verwerking | C22: 0 | D22: 0 | E22: 0 | F22: 0 | G22: 0 | H22: 0 | I22: 1 | J22: 0
A23: 3 | B23: Eindejaarsverrichtingen | C23: 0 | D23: 0 | E23: 0 | F23: 0 | G23: 0 | H23: 0 | I23: 3 | J23: 0
A24: 3 | B24: Resultaatverwerking | C24: 0 | D24: 0 | E24: 0 | F24: 0 | G24: 0 | H24: 0 | I24: 2 | J24: 0

Sheet Bedrijven
A1: Code | B1: Naam | C1: Rol | D1: Adres | E1: Postcode en gemeente | F1: Btw-nummer | G1: IBAN | H1: Wat doet het bedrijf?
A2: NOOR | B2: Fietsatelier Noor bv | C2: eigen bedrijf | D2: Fietsstraat 12 | E2: 3000 Leuven | F2: BE 0999.000.101 | G2: BE00 0000 0000 0101 | H2: fietsenwinkel en -herstelling, zaakvoerder Noor Benali
A3: VELO | B3: Velomax bv | C3: leverancier | D3: Industrieweg 8 | E3: 9000 Gent | F3: BE 0999.000.201 | G3: BE00 0000 0000 0201 | H3: groothandel fietsen
A4: SPAAK | B4: Spaakwerk bv | C4: leverancier | D4: Zandstraat 22 | E4: 3500 Hasselt | F4: BE 0999.000.202 | G4: BE00 0000 0000 0202 | H4: groothandel onderdelen
A5: HELM | B5: HelmHuis bv | C5: leverancier | D5: Kortrijksesteenweg 101 | E5: 8500 Kortrijk | F5: BE 0999.000.203 | G5: BE00 0000 0000 0203 | H5: groothandel helmen en sloten
A6: STROOM | B6: Stroomkracht nv | C6: leverancier | D6: Energielaan 1 | E6: 1000 Brussel | F6: BE 0999.000.204 | G6: BE00 0000 0000 0204 | H6: energieleverancier
A7: NET | B7: Netlink bv | C7: leverancier | D7: Antwerpsesteenweg 5 | E7: 2800 Mechelen | F7: BE 0999.000.205 | G7: BE00 0000 0000 0205 | H7: internet en telefonie
A8: PEET | B8: Drukkerij Peeters bv | C8: leverancier | D8: Diestsestraat 77 | E8: 3000 Leuven | F8: BE 0999.000.206 | G8: BE00 0000 0000 0206 | H8: drukwerk en reclame
A9: NOWAK | B9: Boekhoudkantoor Nowak | C9: leverancier | D9: Tiensesteenweg 150 | E9: 3010 Kessel-Lo | F9: BE 0999.000.207 | G9: BE00 0000 0000 0207 | H9: boekhouder (Marta Nowak)
A10: DEPREZ | B10: Deprez Werkplaatsinrichting bv | C10: leverancier | D10: Ninoofsesteenweg 40 | E10: 1700 Dilbeek | F10: BE 0999.000.208 | G10: BE00 0000 0000 0208 | H10: werkbanken en montagestandaards
A11: KASSA | B11: Kassatech bv | C11: leverancier | D11: Researchpark 3 | E11: 3001 Heverlee | F11: BE 0999.000.209 | G11: BE00 0000 0000 0209 | H11: kassasystemen en computers
A12: MOREAU | B12: Garage Moreau bv | C12: leverancier | D12: Waversesteenweg 200 | E12: 3090 Overijse | F12: BE 0999.000.210 | G12: BE00 0000 0000 0210 | H12: bestelwagens
... A23: ZONNE | B23: Woonzorgcentrum Zonnehof vzw | C23: klant | D23: Kloosterweg 3 | E23: 3020 Herent | F23: BE 0999.000.311 | G23: BE00 0000 0000 0311 | H23: woonzorgcentrum
A24: BANK | B24: Banco Leuven | C24: bank | D24: Ladeuzeplein 1 | E24: 3000 Leuven | H24: bank van Noor, ook kredietgever
A25: LOONW | B25: Loonwijs vzw | C25: leverancier | D25: Brusselsesteenweg 61 | E25: 3000 Leuven | F25: BE 0999.000.211 | G25: BE00 0000 0000 0211 | H25: sociaal secretariaat (vanaf jaar 3)
A26: GERZO | B26: Gerzo Verzekeringen nv | C26: leverancier | D26: Martelarenplein 9 | E26: 3000 Leuven | F26: BE 0999.000.212 | G26: BE00 0000 0000 0212 | H26: verzekeraar (bestelwagen, arbeidsongevallen) (vanaf jaar 3)
A27: VAART | B27: Immo Vaartkom bv | C27: leverancier | D27: Vaartkom 30 | E27: 3000 Leuven | F27: BE 0999.000.213 | G27: BE00 0000 0000 0213 | H27: verhuurt de opslagruimte naast de winkel (vanaf jaar 3)
A28: PREV | B28: Preventa vzw | C28: leverancier | D28: Diestsevest 14 | E28: 3000 Leuven | F28: BE 0999.000.214 | G28: BE00 0000 0000 0214 | H28: externe dienst voor preventie en bescherming op het werk (vanaf jaar 3)

Sheet Artikelen
A1: Code | B1: Omschrijving | C1: Leverancier | D1: Aankoopprijs excl. btw | E1: Verkoopprijs excl. btw | F1: Btw | G1: Verkoopprijs incl. btw (particulier)
A2: STAD | B2: Stadsfiets City, 7 versnellingen | C2: Velomax bv | D2: 400 | E2: 600 | F2: 0.21 | G2: =E2*(1+F2)
A3: EBIKE | B3: E-bike Comfort, 500 Wh | C3: Velomax bv | D3: 1400 | E3: 2000 | F3: 0.21 | G3: =E3*(1+F3)
A4: BAK | B4: Bakfiets Cargo, 2 wielen | C4: Velomax bv | D4: 1800 | E4: 2600 | F4: 0.21 | G4: =E4*(1+F4)
A5: KIND | B5: Kinderfiets 20 inch | C5: Velomax bv | D5: 150 | E5: 250 | F5: 0.21 | G5: =E5*(1+F5)
A6: HELM | B6: Fietshelm Urban | C6: HelmHuis bv | D6: 30 | E6: 50 | F6: 0.21 | G6: =E6*(1+F6)
A7: SLOT | B7: Plooislot | C7: HelmHuis bv | D7: 20 | E7: 35 | F7: 0.21 | G7: =E7*(1+F7)
A8: BAND | B8: Buitenband 28 inch | C8: Spaakwerk bv | D8: 15 | E8: 25 | F8: 0.21 | G8: =E8*(1+F8)
A9: KET | B9: Fietsketting 8 speed | C9: Spaakwerk bv | D9: 10 | E9: 20 | F9: 0.21 | G9: =E9*(1+F9)
A10: LAMP | B10: Verlichtingsset LED | C10: Spaakwerk bv | D10: 25 | E10: 40 | F10: 0.21 | G10: =E10*(1+F10)
A12: Diensten
A13: HERST | B13: Herstelling (arbeid, per stuk) | E13: 50 | F13: 0.06 | G13: =E13*(1+F13)
A14: ONDH | B14: Onderhoudsbeurt (arbeid, per fiets) | E14: 60 | F14: 0.06 | G14: =E14*(1+F14)

Sheet MAR 2e graad
A1: Rekening | B1: Naam | C1: A/P/K/O | D1: Klasse | E1: Klasse omschrijving | F1: Rubriek | G1: Rubriek omschrijving | H1: Gebruikt in de case
A2: 100000 | B2: Geplaatst kapitaal | C2: P | D2: 1 | E2: Eigen vermogen | F2: 10 | G2: Kapitaal | H2: openingsbalans
A3: 140000 | B3: Overgedragen winst | C3: P | D3: 1 | E3: Eigen vermogen | F3: 14 | G3: Overgedragen resultaat | H3: jaar 1 + jaar 2
A4: 141000 | B4: Overgedragen verlies (-) | C4: P | D4: 1 | E4: Eigen vermogen | F4: 14 | G4: Overgedragen resultaat
A5: 173000 | B5: Schulden aan kredietinstellingen | C5: P | D5: 1 | E5: Eigen vermogen | F5: 17 | G5: Schulden op meer dan 1 jaar | H5: jaar 2
A6: 221000 | B6: Gebouwen | C6: A | D6: 2 | E6: Vaste activa | F6: 22 | G6: Terreinen & gebouwen
A7: 221009 | B7: Afschrijvingen op gebouwen (-) | C7: A | D7: 2 | E7: Vaste activa | F7: 22 | G7: Terreinen & gebouwen
A8: 230000 | B8: Installaties | C8: A | D8: 2 | E8: Vaste activa | F8: 23 | G8: Installaties, machines & uitrusting | H8: jaar 1
A9: 230009 | B9: Afschrijvingen op installaties (-) | C9: A | D9: 2 | E9: Vaste activa | F9: 23 | G9: Installaties, machines & uitrusting | H9: jaar 1 + jaar 2
A10: 232000 | B10: Uitrusting | C10: A | D10: 2 | E10: Vaste activa | F10: 23 | G10: Installaties, machines & uitrusting | H10: jaar 1
A11: 232009 | B11: Afschrijvingen op uitrusting (-) | C11: A | D11: 2 | E11: Vaste activa | F11: 23 | G11: Installaties, machines & uitrusting | H11: jaar 1 + jaar 2
A12: 240000 | B12: Meubilair | C12: A | D12: 2 | E12: Vaste activa | F12: 24 | G12: Meubilair & rollend materieel
A13: 240009 | B13: Afschrijvingen op meubilair (-) | C13: A | D13: 2 | E13: Vaste activa | F13: 24 | G13: Meubilair & rollend materieel
A14: 240200 | B14: Computers | C14: A | D14: 2 | E14: Vaste activa | F14: 24 | G14: Meubilair & rollend materieel | H14: jaar 1
A15: 240209 | B15: Afschrijvingen op computers (-) | C15: A | D15: 2 | E15: Vaste activa | F15: 24 | G15: Meubilair & rollend materieel | H15: jaar 1 + jaar 2
A16: 241000 | B16: Rollend materieel | C16: A | D16: 2 | E16: Vaste activa | F16: 24 | G16: Meubilair & rollend materieel | H16: jaar 2
A17: 241009 | B17: Afschrijvingen op rollend materieel (-) | C17: A | D17: 2 | E17: Vaste activa | F17: 24 | G17: Meubilair & rollend materieel | H17: jaar 1 + jaar 2
A18: 340000 | B18: Voorraad handelsgoederen | C18: A | D18: 3 | E18: Voorraden | F18: 34 | G18: Voorraden | H18: jaar 1 + jaar 2
A19: 400000 | B19: Handelsdebiteuren | C19: A | D19: 4 | E19: Vorderingen en schulden op ten hoogste 1 jaar | F19: 40 | G19: Handelsvorderingen | H19: jaar 1 + jaar 2
A20: 411000 | B20: Terug te vorderen btw-saldo | C20: A | D20: 4 | E20: Vorderingen en schulden op ten hoogste 1 jaar | F20: 41 | G20: Overige vorderingen | H20: jaar 2
A21: 411100 | B21: Aftrekbare btw | C21: A | D21: 4 | E21: Vorderingen en schulden op ten hoogste 1 jaar | F21: 41 | G21: Overige vorderingen | H21: jaar 1 + jaar 2
A22: 411200 | B22: Aftrekbare btw op uitgaande creditnota’s | C22: A | D22: 4 | E22: Vorderingen en schulden op ten hoogste 1 jaar | F22: 41 | G22: Overige vorderingen | H22: jaar 1 + jaar 2
A23: 418000 | B23: Terug te vorderen verpakking | C23: A | D23: 4 | E23: Vorderingen en schulden op ten hoogste 1 jaar | F23: 41 | G23: Overige vorderingen | H23: jaar 2
A24: 423000 | B24: Binnen het jaar vervallende schulden aan kredietinstellingen | C24: P | D24: 4 | E24: Vorderingen en schulden op ten hoogste 1 jaar | F24: 42 | G24: Schulden op maar dan 1 jaar die binnen het jaar vervallen
A25: 440000 | B25: Leveranciers | C25: P | D25: 4 | E25: Vorderingen en schulden op ten hoogste 1 jaar | F25: 44 | G25: Handelsschulden | H25: jaar 1 + jaar 2
A26: 451000 | B26: Te betalen btw-saldo | C26: P | D26: 4 | E26: Vorderingen en schulden op ten hoogste 1 jaar | F26: 45 | G26: Schulden mbt belastingen, ... | H26: jaar 1 + jaar 2
A27: 451100 | B27: Verschuldigde btw | C27: P | D27: 4 | E27: Vorderingen en schulden op ten hoogste 1 jaar | F27: 45 | G27: Schulden mbt belastingen, ... | H27: jaar 1 + jaar 2
A28: 451200 | B28: Verschuldigde btw op inkomende creditnota’s | C28: P | D28: 4 | E28: Vorderingen en schulden op ten hoogste 1 jaar | F28: 45 | G28: Schulden mbt belastingen, ... | H28: jaar 1 + jaar 2
A29: 488000 | B29: Terug te betalen verpakking | C29: P | D29: 4 | E29: Vorderingen en schulden op ten hoogste 1 jaar | F29: 48 | G29: Diverse schulden | H29: jaar 2
A30: 550000 | B30: Bankrekening | C30: A | D30: 5 | E30: Liquide middelen | F30: 55 | G30: Bank | H30: jaar 1 + jaar 2
A31: 570000 | B31: Kas | C31: A | D31: 5 | E31: Liquide middelen | F31: 57 | G31: Kas | H31: jaar 1 + jaar 2
A32: 580000 | B32: Interne overboekingen | C32: A | D32: 5 | E32: Liquide middelen | F32: 58 | G32: Interne overboekingen | H32: jaar 2
A33: 600000 | B33: Aankopen grondstoffen | C33: K | D33: 6 | E33: Kosten | F33: 60 | G33: Handelsgoederen, grond- en hulpstoffen
A34: 604000 | B34: Aankopen handelsgoederen | C34: K | D34: 6 | E34: Kosten | F34: 60 | G34: Handelsgoederen, grond- en hulpstoffen | H34: jaar 1 + jaar 2
A35: 604010 | B35: Retours op aankopen (-) | C35: K | D35: 6 | E35: Kosten | F35: 60 | G35: Handelsgoederen, grond- en hulpstoffen | H35: jaar 1 + jaar 2
A36: 604020 | B36: Handelskorting op aankopen (-) | C36: K | D36: 6 | E36: Kosten | F36: 60 | G36: Handelsgoederen, grond- en hulpstoffen | H36: jaar 2
A37: 604030 | B37: Aankoopkosten | C37: K | D37: 6 | E37: Kosten | F37: 60 | G37: Handelsgoederen, grond- en hulpstoffen | H37: jaar 2
A38: 609400 | B38: Voorraadwijzigingen handelsgoederen | C38: K | D38: 6 | E38: Kosten | F38: 60 | G38: Handelsgoederen, grond- en hulpstoffen | H38: jaar 1 + jaar 2
A39: 611000 | B39: Huur en huurlasten | C39: K | D39: 6 | E39: Kosten | F39: 61 | G39: Diensten en diverse goederen
A40: 611800 | B40: Onderhoud en herstellingen rollend materieel | C40: K | D40: 6 | E40: Kosten | F40: 61 | G40: Diensten en diverse goederen
...

Sheet J1 Lijnen
A1: ID | B1: Documentnr | C1: Soort doc | D1: Lijn | E1: Soort lijn | F1: Artikel | G1: Omschrijving | H1: Aantal | I1: Eenheidsprijs | J1: Bedrag excl. btw | K1: Btw % | L1: Btw
A2: C01 | B2: 2026-118 | C2: AK | D2: 1 | E2: artikel | F2: STAD | G2: Stadsfiets City, 7 versnellingen | H2: 10 | I2: 400 | J2: =H2*I2 | K2: 0.21 | L2: =J2*K2
A3: C02 | B3: SK-26-0457 | C3: AK | D3: 1 | E3: dienst | G3: Elektriciteit januari 2026 (voorschot) | H3: 1 | I3: 200 | J3: =H3*I3 | K3: 0.21 | L3: =J3*K3
A4: C03 | B4: DW-2026-012 | C4: AK | D4: 1 | E4: vast actief | G4: Werkbank met bankschroef en gereedschapswand | H4: 1 | I4: 1500 | J4: =H4*I4 | K4: 0.21 | L4: =J4*K4
A5: C04 | B5: 2026-001 | C5: VK | D5: 1 | E5: artikel | F5: STAD | G5: Stadsfiets City, 7 versnellingen | H5: 10 | I5: 600 | J5: =H5*I5 | K5: 0.21 | L5: =J5*K5
A6: C05 | B6: 2026-002 | C6: VK | D6: 1 | E6: artikel | F6: STAD | G6: Stadsfiets City, 7 versnellingen | H6: 4 | I6: 600 | J6: =H6*I6 | K6: 0.21 | L6: =J6*K6
A7: C06 | B7: CN-2026-001 | C7: CN-VK | D7: 1 | E7: artikel | F7: STAD | G7: Stadsfiets City, 7 versnellingen | H7: 1 | I7: 600 | J7: =H7*I7 | K7: 0.21 | L7: =J7*K7
A8: C07 | B8: CN-2026-007 | C8: CN-AK | D8: 1 | E8: artikel | F8: STAD | G8: Stadsfiets City, 7 versnellingen | H8: 1 | I8: 400 | J8: =H8*I8 | K8: 0.21 | L8: =J8*K8
A9: C08 | B9: DO-2026-01 | C9: DO | D9: 1 | E9: artikel | F9: STAD | G9: Stadsfiets City, 7 versnellingen | H9: 1 | I9: 600 | J9: =H9*I9 | K9: 0.21 | L9: =J9*K9
A10: C08 | B10: DO-2026-01 | C10: DO | D10: 2 | E10: artikel | F10: HELM | G10: Fietshelm Urban | H10: 6 | I10: 50 | J10: =H10*I10 | K10: 0.21 | L10: =J10*K10
A11: C08 | B11: DO-2026-01 | C11: DO | D11: 3 | E11: artikel | F11: BAND | G11: Buitenband 28 inch | H11: 4 | I11: 25 | J11: =H11*I11 | K11: 0.21 | L11: =J11*K11
A12: C08 | B12: DO-2026-01 | C12: DO | D12: 4 | E12: dienst | G12: Herstelling fiets (arbeid) | H12: 4 | I12: 50 | J12: =H12*I12 | K12: 0.06 | L12: =J12*K12
A13: A1 | B13: 2026-205 | C13: AK | D13: 1 | E13: artikel | F13: STAD | G13: Stadsfiets City, 7 versnellingen | H13: 12 | I13: 400 | J13: =H13*I13 | K13: 0.21 | L13: =J13*K13
A14: A1 | B14: 2026-205 | C14: AK | D14: 2 | E14: artikel | F14: EBIKE | G14: E-bike Comfort, 500 Wh | H14: 5 | I14: 1400 | J14: =H14*I14 | K14: 0.21 | L14: =J14*K14
A15: A1 | B15: 2026-205 | C15: AK | D15: 3 | E15: artikel | F15: BAK | G15: Bakfiets Cargo, 2 wielen | H15: 2 | I15: 1800 | J15: =H15*I15 | K15: 0.21 | L15: =J15*K15
A16: A2 | B16: SW-1032 | C16: AK | D16: 1 | E16: artikel | F16: BAND | G16: Buitenband 28 inch | H16: 20 | I16: 15 | J16: =H16*I16 | K16: 0.21 | L16: =J16*K16
A17: A2 | B17: SW-1032 | C17: AK | D17: 2 | E17: artikel | F17: KET | G17: Fietsketting 8 speed | H17: 10 | I17: 10 | J17: =H17*I17 | K17: 0.21 | L17: =J17*K17
A18: A3 | B18: HH-26-077 | C18: AK | D18: 1 | E18: artikel | F18: HELM | G18: Fietshelm Urban | H18: 20 | I18: 30 | J18: =H18*I18 | K18: 0.21 | L18: =J18*K18
A19: A3 | B19: HH-26-077 | C19: AK | D19: 2 | E19: artikel | F19: SLOT | G19: Plooislot | H19: 20 | I19: 20 | J19: =H19*I19 | K19: 0.21 | L19: =J19*K19
A20: A4 | B20: DP-2026-031 | C20: AK | D20: 1 | E20: dienst | G20: 2.000 flyers en 20 affiches opening voorjaar | H20: 1 | I20: 500 | J20: =H20*I20 | K20: 0.21 | L20: =J20*K20
A21: A5 | B21: KT-0458 | C21: AK | D21: 1 | E21: vast actief | G21: Kassasysteem met touchscreen, bonprinter en kassalade | H21: 1 | I21: 1200 | J21: =H21*I21 | K21: 0.21 | L21: =J21*K21
A22: CA1 | B22: CN-2026-015 | C22: CN-AK | D22: 1 | E22: artikel | F22: EBIKE | G22: E-bike Comfort, 500 Wh | H22: 1 | I22: 1400 | J22: =H22*I22 | K22: 0.21 | L22: =J22*K22
A23: CA2 | B23: HH-CN-26-004 | C23: CN-AK | D23: 1 | E23: artikel | F23: SLOT | G23: Plooislot | H23: 10 | I23: 20 | J23: =H23*I23 | K23: 0.21 | L23: =J23*K23
A24: CA3 | B24: SW-CN-118 | C24: CN-AK | D24: 1 | E24: artikel | F24: KET | G24: Fietsketting 8 speed | H24: 10 | I24: 10 | J24: =H24*I24 | K24: 0.21 | L24: =J24*K24
A25: V1 | B25: 2026-003 | C25: VK | D25: 1 | E25: artikel | F25: STAD | G25: Stadsfiets City, 7 versnellingen | H25: 8 | I25: 600 | J25: =H25*I25 | K25: 0.21 | L25: =J25*K25
A26: V2 | B26: 2026-004 | C26: VK | D26: 1 | E26: artikel | F26: BAK | G26: Bakfiets Cargo, 2 wielen | H26: 2 | I26: 2600 | J26: =H26*I26 | K26: 0.21 | L26: =J26*K26
A27: V3 | B27: 2026-005 | C27: VK | D27: 1 | E27: artikel | F27: EBIKE | G27: E-bike Comfort, 500 Wh | H27: 3 | I27: 2000 | J27: =H27*I27 | K27: 0.21 | L27: =J27*K27
A28: V4 | B28: 2026-006 | C28: VK | D28: 1 | E28: dienst | G28: Onderhoudsbeurt fiets (arbeid) | H28: 10 | I28: 60 | J28: =H28*I28 | K28: 0.06 | L28: =J28*K28
A29: V5 | B29: 2026-007 | C29: VK | D29: 1 | E29: artikel | F29: STAD | G29: Stadsfiets City, 7 versnellingen | H29: 2 | I29: 600 | J29: =H29*I29 | K29: 0.21 | L29: =J29*K29
A30: V5 | B30: 2026-007 | C30: VK | D30: 2 | E30: artikel | F30: HELM | G30: Fietshelm Urban | H30: 4 | I30: 50 | J30: =H30*I30 | K30: 0.21 | L30: =J30*K30
A31: CV1 | B31: CN-2026-002 | C31: CN-VK | D31: 1 | E31: artikel | F31: STAD | G31: Stadsfiets City, 7 versnellingen | H31: 1 | I31: 600 | J31: =H31*I31 | K31: 0.21 | L31: =J31*K31
A32: CV2 | B32: CN-2026-003 | C32: CN-VK | D32: 1 | E32: artikel | F32: HELM | G32: Fietshelm Urban | H32: 2 | I32: 50 | J32: =H32*I32 | K32: 0.21 | L32: =J32*K32
A33: CV3 | B33: CN-2026-004 | C33: CN-VK | D33: 1 | E33: artikel | F33: EBIKE | G33: E-bike Comfort, 500 Wh | H33: 1 | I33: 2000 | J33: =H33*I33 | K33: 0.21 | L33: =J33*K33
A34: D1 | B34: DO-2026-02 | C34: DO | D34: 1 | E34: artikel | F34: STAD | G34: Stadsfiets City, 7 versnellingen | H34: 2 | I34: 600 | J34: =H34*I34 | K34: 0.21 | L34: =J34*K34
A35: D1 | B35: DO-2026-02 | C35: DO | D35: 2 | E35: artikel | F35: HELM | G35: Fietshelm Urban | H35: 6 | I35: 50 | J35: =H35*I35 | K35: 0.21 | L35: =J35*K35
A36: D1 | B36: DO-2026-02 | C36: DO | D36: 3 | E36: dienst | G36: Herstelling fiets (arbeid) | H36: 6 | I36: 50 | J36: =H36*I36 | K36: 0.06 | L36: =J36*K36
A37: D2 | B37: DO-2026-03 | C37: DO | D37: 1 | E37: artikel | F37: EBIKE | G37: E-bike Comfort, 500 Wh | H37: 1 | I37: 2000 | J37: =H37*I37 | K37: 0.21 | L37: =J37*K37
A38: D2 | B38: DO-2026-03 | C38: DO | D38: 2 | E38: dienst | G38: Herstelling fiets (arbeid) | H38: 8 | I38: 50 | J38: =H38*I38 | K38: 0.06 | L38: =J38*K38
A39: D3 | B39: DO-2026-04 | C39: DO | D39: 1 | E39: artikel | F39: BAND | G39: Buitenband 28 inch | H39: 20 | I39: 25 | J39: =H39*I39 | K39: 0.21 | L39: =J39*K39
A40: D3 | B40: DO-2026-04 | C40: DO | D40: 2 | E40: artikel | F40: HELM | G40: Fietshelm Urban | H40: 8 | I40: 50 | J40: =H40*I40 | K40: 0.21 | L40: =J40*K40
...

Sheet J1 Documenten
A1: Volgorde in set | B1: ID | C1: Set | D1: Kwartaal | E1: Soort | F1: Subsoort | G1: Datum | H1: Vervaldag | I1: Documentnr | J1: Van | K1: Aan | L1: Verwijst naar | M1: Reden / omschrijving | N1: MvH 21% | O1: Btw 21% | P1: MvH 6% | Q1: Btw 6% | R1: Waarborg | S1: Fin. korting (niet afgetrokken) | T1: Totaal (te betalen) | U1: Te betalen binnen kortingstermijn | V1: Contant (kas) | W1: Bancontact | X1: Betaald via uittreksel | Y1: Controle D-C | Z1: Opmerking
A2: 1 | B2: C01 | C2: CURSUS | D2: K1 | E2: AK | F2: handelsgoederen | G2: 46027 | H2: =G2+30 | I2: 2026-118 | J2: Velomax bv | K2: Fietsatelier Noor bv | N2: =SUMIFS('J1 Lijnen'!$J:$J,'J1 Lijnen'!$A:$A,$B2,'J1 Lijnen'!$K:$K,0.21,'J1 Lijnen'!$E:$E,"<>verpakking") | O2: =SUMIFS('J1 Lijnen'!$L:$L,'J1 Lijnen'!$A:$A,$B2,'J1 Lijnen'!$K:$K,0.21) | P2: =SUMIFS('J1 Lijnen'!$J:$J,'J1 Lijnen'!$A:$A,$B2,'J1 Lijnen'!$K:$K,0.06) | Q2: =SUMIFS('J1 Lijnen'!$L:$L,'J1 Lijnen'!$A:$A,$B2,'J1 Lijnen'!$K:$K,0.06) | R2: =SUMIFS('J1 Lijnen'!$J:$J,'J1 Lijnen'!$A:$A,$B2,'J1 Lijnen'!$E:$E,"verpakking") | S2: =-SUMIFS('J1 Lijnen'!$J:$J,'J1 Lijnen'!$A:$A,$B2,'J1 Lijnen'!$E:$E,"financiële korting") | T2: =SUM(N2:S2) | X2: U2026-01 | Y2: =SUMIFS('J1 Journaal'!$K:$K,'J1 Journaal'!$E:$E,$B2)-SUMIFS('J1 Journaal'!$L:$L,'J1 Journaal'!$E:$E,$B2)
A3: 2 | B3: C02 | C3: CURSUS | D3: K1 | E3: AK | F3: diensten | G3: 46029 | H3: =G3+30 | I3: SK-26-0457 | J3: Stroomkracht nv | K3: Fietsatelier Noor bv | N3: =SUMIFS('J1 Lijnen'!$J:$J,'J1 Lijnen'!$A:$A,$B3,'J1 Lijnen'!$K:$K,0.21,'J1 Lijnen'!$E:$E,"<>verpakking") | O3: =SUMIFS('J1 Lijnen'!$L:$L,'J1 Lijnen'!$A:$A,$B3,'J1 Lijnen'!$K:$K,0.21) | P3: =SUMIFS('J1 Lijnen'!$J:$J,'J1 Lijnen'!$A:$A,$B3,'J1 Lijnen'!$K:$K,0.06) | Q3: =SUMIFS('J1 Lijnen'!$L:$L,'J1 Lijnen'!$A:$A,$B3,'J1 Lijnen'!$K:$K,0.06) | R3: =SUMIFS('J1 Lijnen'!$J:$J,'J1 Lijnen'!$A:$A,$B3,'J1 Lijnen'!$E:$E,"verpakking") | S3: =-SUMIFS('J1 Lijnen'!$J:$J,'J1 Lijnen'!$A:$A,$B3,'J1 Lijnen'!$E:$E,"financiële korting") | T3: =SUM(N3:S3) | X3: U2026-01 | Y3: =SUMIFS('J1 Journaal'!$K:$K,'J1 Journaal'!$E:$E,$B3)-SUMIFS('J1 Journaal'!$L:$L,'J1 Journaal'!$E:$E,$B3)
A4: 3 | B4: C03 | C4: CURSUS | D4: K1 | E4: AK | F4: vaste activa | G4: 46031 | H4: =G4+30 | I4: DW-2026-012 | J4: Deprez Werkplaatsinrichting bv | K4: Fietsatelier Noor bv | N4: =SUMIFS('J1 Lijnen'!$J:$J,'J1 Lijnen'!$A:$A,$B4,'J1 Lijnen'!$K:$K,0.21,'J1 Lijnen'!$E:$E,"<>verpakking") | O4: =SUMIFS('J1 Lijnen'!$L:$L,'J1 Lijnen'!$A:$A,$B4,'J1 Lijnen'!$K:$K,0.21) | P4: =SUMIFS('J1 Lijnen'!$J:$J,'J1 Lijnen'!$A:$A,$B4,'J1 Lijnen'!$K:$K,0.06) | Q4: =SUMIFS('J1 Lijnen'!$L:$L,'J1 Lijnen'!$A:$A,$B4,'J1 Lijnen'!$K:$K,0.06) | R4: =SUMIFS('J1 Lijnen'!$J:$J,'J1 Lijnen'!$A:$A,$B4,'J1 Lijnen'!$E:$E,"verpakking") | S4: =-SUMIFS('J1 Lijnen'!$J:$J,'J1 Lijnen'!$A:$A,$B4,'J1 Lijnen'!$E:$E,"financiële korting") | T4: =SUM(N4:S4) | X4: U2026-01 | Y4: =SUMIFS('J1 Journaal'!$K:$K,'J1 Journaal'!$E:$E,$B4)-SUMIFS('J1 Journaal'!$L:$L,'J1 Journaal'!$E:$E,$B4)
A5: 4 | B5: C04 | C5: CURSUS | D5: K1 | E5: VK | F5: handelsgoederen | G5: 46036 | H5: =G5+30 | I5: 2026-001 | J5: Fietsatelier Noor bv | K5: Snelpost bv | N5: =SUMIFS('J1 Lijnen'!$J:$J,'J1 Lijnen'!$A:$A,$B5,'J1 Lijnen'!$K:$K,0.21,'J1 Lijnen'!$E:$E,"<>verpakking") | O5: =SUMIFS('J1 Lijnen'!$L:$L,'J1 Lijnen'!$A:$A,$B5,'J1 Lijnen'!$K:$K,0.21) | P5: =SUMIFS('J1 Lijnen'!$J:$J,'J1 Lijnen'!$A:$A,$B5,'J1 Lijnen'!$K:$K,0.06) | Q5: =SUMIFS('J1 Lijnen'!$L:$L,'J1 Lijnen'!$A:$A,$B5,'J1 Lijnen'!$K:$K,0.06) | R5: =SUMIFS('J1 Lijnen'!$J:$J,'J1 Lijnen'!$A:$A,$B5,'J1 Lijnen'!$E:$E,"verpakking") | S5: =-SUMIFS('J1 Lijnen'!$J:$J,'J1 Lijnen'!$A:$A,$B5,'J1 Lijnen'!$E:$E,"financiële korting") | T5: =SUM(N5:S5) | X5: U2026-02 | Y5: =SUMIFS('J1 Journaal'!$K:$K,'J1 Journaal'!$E:$E,$B5)-SUMIFS('J1 Journaal'!$L:$L,'J1 Journaal'!$E:$E,$B5)
A6: 5 | B6: C05 | C6: CURSUS | D6: K1 | E6: VK | F6: handelsgoederen | G6: 46041 | H6: =G6+30 | I6: 2026-002 | J6: Fietsatelier Noor bv | K6: Hotel De Linde bv | N6: =SUMIFS('J1 Lijnen'!$J:$J,'J1 Lijnen'!$A:$A,$B6,'J1 Lijnen'!$K:$K,0.21,'J1 Lijnen'!$E:$E,"<>verpakking") | O6: =SUMIFS('J1 Lijnen'!$L:$L,'J1 Lijnen'!$A:$A,$B6,'J1 Lijnen'!$K:$K,0.21) | P6: =SUMIFS('J1 Lijnen'!$J:$J,'J1 Lijnen'!$A:$A,$B6,'J1 Lijnen'!$K:$K,0.06) | Q6: =SUMIFS('J1 Lijnen'!$L:$L,'J1 Lijnen'!$A:$A,$B6,'J1 Lijnen'!$K:$K,0.06) | R6: =SUMIFS('J1 Lijnen'!$J:$J,'J1 Lijnen'!$A:$A,$B6,'J1 Lijnen'!$E:$E,"verpakking") | S6: =-SUMIFS('J1 Lijnen'!$J:$J,'J1 Lijnen'!$A:$A,$B6,'J1 Lijnen'!$E:$E,"financiële korting") | T6: =SUM(N6:S6) | X6: U2026-03 | Y6: =SUMIFS('J1 Journaal'!$K:$K,'J1 Journaal'!$E:$E,$B6)-SUMIFS('J1 Journaal'!$L:$L,'J1 Journaal'!$E:$E,$B6)
A7: 7 | B7: C06 | C7: CURSUS | D7: K1 | E7: CN-VK | F7: retour | G7: 46043 | I7: CN-2026-001 | J7: Fietsatelier Noor bv | K7: Hotel De Linde bv | L7: 2026-002 | M7: 1 fiets teruggenomen: kras op het frame | N7: =SUMIFS('J1 Lijnen'!$J:$J,'J1 Lijnen'!$A:$A,$B7,'J1 Lijnen'!$K:$K,0.21,'J1 Lijnen'!$E:$E,"<>verpakking") | O7: =SUMIFS('J1 Lijnen'!$L:$L,'J1 Lijnen'!$A:$A,$B7,'J1 Lijnen'!$K:$K,0.21) | P7: =SUMIFS('J1 Lijnen'!$J:$J,'J1 Lijnen'!$A:$A,$B7,'J1 Lijnen'!$K:$K,0.06) | Q7: =SUMIFS('J1 Lijnen'!$L:$L,'J1 Lijnen'!$A:$A,$B7,'J1 Lijnen'!$K:$K,0.06) | R7: =SUMIFS('J1 Lijnen'!$J:$J,'J1 Lijnen'!$A:$A,$B7,'J1 Lijnen'!$E:$E,"verpakking") | S7: =-SUMIFS('J1 Lijnen'!$J:$J,'J1 Lijnen'!$A:$A,$B7,'J1 Lijnen'!$E:$E,"financiële korting") | T7: =SUM(N7:S7) | X7: U2026-03 | Y7: =SUMIFS('J1 Journaal'!$K:$K,'J1 Journaal'!$E:$E,$B7)-SUMIFS('J1 Journaal'!$L:$L,'J1 Journaal'!$E:$E,$B7)
A8: 8 | B8: C07 | C8: CURSUS | D8: K1 | E8: CN-AK | F8: retour | G8: 46044 | I8: CN-2026-007 | J8: Velomax bv | K8: Fietsatelier Noor bv | L8: 2026-118 | M8: 1 fiets beschadigd geleverd, teruggestuurd | N8: =SUMIFS('J1 Lijnen'!$J:$J,'J1 Lijnen'!$A:$A,$B8,'J1 Lijnen'!$K:$K,0.21,'J1 Lijnen'!$E:$E,"<>verpakking") | O8: =SUMIFS('J1 Lijnen'!$L:$L,'J1 Lijnen'!$A:$A,$B8,'J1 Lijnen'!$K:$K,0.21) | P8: =SUMIFS('J1 Lijnen'!$J:$J,'J1 Lijnen'!$A:$A,$B8,'J1 Lijnen'!$K:$K,0.06) | Q8: =SUMIFS('J1 Lijnen'!$L:$L,'J1 Lijnen'!$A:$A,$B8,'J1 Lijnen'!$K:$K,0.06) | R8: =SUMIFS('J1 Lijnen'!$J:$J,'J1 Lijnen'!$A:$A,$B8,'J1 Lijnen'!$E:$E,"verpakking") | S8: =-SUMIFS('J1 Lijnen'!$J:$J,'J1 Lijnen'!$A:$A,$B8,'J1 Lijnen'!$E:$E,"financiële korting") | T8: =SUM(N8:S8) | X8: U2026-03 | Y8: =SUMIFS('J1 Journaal'!$K:$K,'J1 Journaal'!$E:$E,$B8)-SUMIFS('J1 Journaal'!$L:$L,'J1 Journaal'!$E:$E,$B8)
A9: 9 | B9: C08 | C9: CURSUS | D9: K1 | E9: DO | F9: dagontvangst | G9: 46046 | I9: DO-2026-01 | J9: Fietsatelier Noor bv | K9: particulieren (kasticket) | M9: Dagontvangsten winkel (verkopen aan particulieren) | N9: =SUMIFS('J1 Lijnen'!$J:$J,'J1 Lijnen'!$A:$A,$B9,'J1 Lijnen'!$K:$K,0.21,'J1 Lijnen'!$E:$E,"<>verpakking") | O9: =SUMIFS('J1 Lijnen'!$L:$L,'J1 Lijnen'!$A:$A,$B9,'J1 Lijnen'!$K:$K,0.21) | P9: =SUMIFS('J1 Lijnen'!$J:$J,'J1 Lijnen'!$A:$A,$B9,'J1 Lijnen'!$K:$K,0.06) | Q9: =SUMIFS('J1 Lijnen'!$L:$L,'J1 Lijnen'!$A:$A,$B9,'J1 Lijnen'!$K:$K,0.06) | R9: =SUMIFS('J1 Lijnen'!$J:$J,'J1 Lijnen'!$A:$A,$B9,'J1 Lijnen'!$E:$E,"verpakking") | S9: =-SUMIFS('J1 Lijnen'!$J:$J,'J1 Lijnen'!$A:$A,$B9,'J1 Lijnen'!$E:$E,"financiële korting") | T9: =SUM(N9:S9) | V9: =T9-W9 | W9: 1000 | X9: C08K, U2026-03 | Y9: =SUMIFS('J1 Journaal'!$K:$K,'J1 Journaal'!$E:$E,$B9)-SUMIFS('J1 Journaal'!$L:$L,'J1 Journaal'!$E:$E,$B9)
A10: 10 | B10: C08K | C10: CURSUS | D10: K1 | E10: KAS | F10: ontvangst | G10: 46046 | I10: Kasboek DO-2026-01 | J10: Fietsatelier Noor bv | K10: Fietsatelier Noor bv | L10: DO-2026-01 | M10: Contant deel van dagontvangst DO-2026-01 (laat de vordering op de klanten dalen) | T10: 422 | V10: 422 | Y10: =SUMIFS('J1 Journaal'!$K:$K,'J1 Journaal'!$E:$E,$B10)-SUMIFS('J1 Journaal'!$L:$L,'J1 Journaal'!$E:$E,$B10)
A11: 1 | B11: A1 | C11: VERPLICHT | D11: K1 | E11: AK | F11: handelsgoederen | G11: 46055 | H11: =G11+30 | I11: 2026-205 | J11: Velomax bv | K11: Fietsatelier Noor bv | N11: =SUMIFS('J1 Lijnen'!$J:$J,'J1 Lijnen'!$A:$A,$B11,'J1 Lijnen'!$K:$K,0.21,'J1 Lijnen'!$E:$E,"<>verpakking") | O11: =SUMIFS('J1 Lijnen'!$L:$L,'J1 Lijnen'!$A:$A,$B11,'J1 Lijnen'!$K:$K,0.21) | P11: =SUMIFS('J1 Lijnen'!$J:$J,'J1 Lijnen'!$A:$A,$B11,'J1 Lijnen'!$K:$K,0.06) | Q11: =SUMIFS('J1 Lijnen'!$L:$L,'J1 Lijnen'!$A:$A,$B11,'J1 Lijnen'!$K:$K,0.06) | R11: =SUMIFS('J1 Lijnen'!$J:$J,'J1 Lijnen'!$A:$A,$B11,'J1 Lijnen'!$E:$E,"verpakking") | S11: =-SUMIFS('J1 Lijnen'!$J:$J,'J1 Lijnen'!$A:$A,$B11,'J1 Lijnen'!$E:$E,"financiële korting") | T11: =SUM(N11:S11) | X11: U2026-06 | Y11: =SUMIFS('J1 Journaal'!$K:$K,'J1 Journaal'!$E:$E,$B11)-SUMIFS('J1 Journaal'!$L:$L,'J1 Journaal'!$E:$E,$B11)
A12: 2 | B12: A2 | C12: VERPLICHT | D12: K1 | E12: AK | F12: handelsgoederen | G12: 46057 | H12: =G12+30 | I12: SW-1032 | J12: Spaakwerk bv | K12: Fietsatelier Noor bv | N12: =SUMIFS('J1 Lijnen'!$J:$J,'J1 Lijnen'!$A:$A,$B12,'J1 Lijnen'!$K:$K,0.21,'J1 Lijnen'!$E:$E,"<>verpakking") | O12: =SUMIFS('J1 Lijnen'!$L:$L,'J1 Lijnen'!$A:$A,$B12,'J1 Lijnen'!$K:$K,0.21) | P12: =SUMIFS('J1 Lijnen'!$J:$J,'J1 Lijnen'!$A:$A,$B12,'J1 Lijnen'!$K:$K,0.06) | Q12: =SUMIFS('J1 Lijnen'!$L:$L,'J1 Lijnen'!$A:$A,$B12,'J1 Lijnen'!$K:$K,0.06) | R12: =SUMIFS('J1 Lijnen'!$J:$J,'J1 Lijnen'!$A:$A,$B12,'J1 Lijnen'!$E:$E,"verpakking") | S12: =-SUMIFS('J1 Lijnen'!$J:$J,'J1 Lijnen'!$A:$A,$B12,'J1 Lijnen'!$E:$E,"financiële korting") | T12: =SUM(N12:S12) | X12: U2026-05 | Y12: =SUMIFS('J1 Journaal'!$K:$K,'J1 Journaal'!$E:$E,$B12)-SUMIFS('J1 Journaal'!$L:$L,'J1 Journaal'!$E:$E,$B12)
A13: 3 | B13: A3 | C13: VERPLICHT | D13: K1 | E13: AK | F13: handelsgoederen | G13: 46059 | H13: =G13+30 | I13: HH-26-077 | J13: HelmHuis bv | K13: Fietsatelier Noor bv | N13: =SUMIFS('J1 Lijnen'!$J:$J,'J1 Lijnen'!$A:$A,$B13,'J1 Lijnen'!$K:$K,0.21,'J1 Lijnen'!$E:$E,"<>verpakking") | O13: =SUMIFS('J1 Lijnen'!$L:$L,'J1 Lijnen'!$A:$A,$B13,'J1 Lijnen'!$K:$K,0.21) | P13: =SUMIFS('J1 Lijnen'!$J:$J,'J1 Lijnen'!$A:$A,$B13,'J1 Lijnen'!$K:$K,0.06) | Q13: =SUMIFS('J1 Lijnen'!$L:$L,'J1 Lijnen'!$A:$A,$B13,'J1 Lijnen'!$K:$K,0.06) | R13: =SUMIFS('J1 Lijnen'!$J:$J,'J1 Lijnen'!$A:$A,$B13,'J1 Lijnen'!$E:$E,"verpakking") | S13: =-SUMIFS('J1 Lijnen'!$J:$J,'J1 Lijnen'!$A:$A,$B13,'J1 Lijnen'!$E:$E,"financiële korting") | T13: =SUM(N13:S13) | X13: U2026-05 | Y13: =SUMIFS('J1 Journaal'!$K:$K,'J1 Journaal'!$E:$E,$B13)-SUMIFS('J1 Journaal'!$L:$L,'J1 Journaal'!$E:$E,$B13)
A14: 4 | B14: A4 | C14: VERPLICHT | D14: K1 | E14: AK | F14: diensten | G14: 46062 | H14: =G14+30 | I14: DP-2026-031 | J14: Drukkerij Peeters bv | K14: Fietsatelier Noor bv | N14: =SUMIFS('J1 Lijnen'!$J:$J,'J1 Lijnen'!$A:$A,$B14,'J1 Lijnen'!$K:$K,0.21,'J1 Lijnen'!$E:$E,"<>verpakking") | O14: =SUMIFS('J1 Lijnen'!$L:$L,'J1 Lijnen'!$A:$A,$B14,'J1 Lijnen'!$K:$K,0.21) | P14: =SUMIFS('J1 Lijnen'!$J:$J,'J1 Lijnen'!$A:$A,$B14,'J1 Lijnen'!$K:$K,0.06) | Q14: =SUMIFS('J1 Lijnen'!$L:$L,'J1 Lijnen'!$A:$A,$B14,'J1 Lijnen'!$K:$K,0.06) | R14: =SUMIFS('J1 Lijnen'!$J:$J,'J1 Lijnen'!$A:$A,$B14,'J1 Lijnen'!$E:$E,"verpakking") | S14: =-SUMIFS('J1 Lijnen'!$J:$J,'J1 Lijnen'!$A:$A,$B14,'J1 Lijnen'!$E:$E,"financiële korting") | T14: =SUM(N14:S14) | X14: U2026-06 | Y14: =SUMIFS('J1 Journaal'!$K:$K,'J1 Journaal'!$E:$E,$B14)-SUMIFS('J1 Journaal'!$L:$L,'J1 Journaal'!$E:$E,$B14)
A15: 5 | B15: A5 | C15: VERPLICHT | D15: K1 | E15: AK | F15: vaste activa | G15: 46064 | H15: =G15+30 | I15: KT-0458 | J15: Kassatech bv | K15: Fietsatelier Noor bv | N15: =SUMIFS('J1 Lijnen'!$J:$J,'J1 Lijnen'!$A:$A,$B15,'J1 Lijnen'!$K:$K,0.21,'J1 Lijnen'!$E:$E,"<>verpakking") | O15: =SUMIFS('J1 Lijnen'!$L:$L,'J1 Lijnen'!$A:$A,$B15,'J1 Lijnen'!$K:$K,0.21) | P15: =SUMIFS('J1 Lijnen'!$J:$J,'J1 Lijnen'!$A:$A,$B15,'J1 Lijnen'!$K:$K,0.06) | Q15: =SUMIFS('J1 Lijnen'!$L:$L,'J1 Lijnen'!$A:$A,$B15,'J1 Lijnen'!$K:$K,0.06) | R15: =SUMIFS('J1 Lijnen'!$J:$J,'J1 Lijnen'!$A:$A,$B15,'J1 Lijnen'!$E:$E,"verpakking") | S15: =-SUMIFS('J1 Lijnen'!$J:$J,'J1 Lijnen'!$A:$A,$B15,'J1 Lijnen'!$E:$E,"financiële korting") | T15: =SUM(N15:S15) | X15: U2026-06 | Y15: =SUMIFS('J1 Journaal'!$K:$K,'J1 Journaal'!$E:$E,$B15)-SUMIFS('J1 Journaal'!$L:$L,'J1 Journaal'!$E:$E,$B15)
A16: 6 | B16: CA1 | C16: VERPLICHT | D16: K1 | E16: CN-AK | F16: retour | G16: 46066 | I16: CN-2026-015 | J16: Velomax bv | K16: Fietsatelier Noor bv | L16: 2026-205 | M16: 1 e-bike in verkeerde framemaat geleverd, teruggestuurd | N16: =SUMIFS('J1 Lijnen'!$J:$J,'J1 Lijnen'!$A:$A,$B16,'J1 Lijnen'!$K:$K,0.21,'J1 Lijnen'!$E:$E,"<>verpakking") | O16: =SUMIFS('J1 Lijnen'!$L:$L,'J1 Lijnen'!$A:$A,$B16,'J1 Lijnen'!$K:$K,0.21) | P16: =SUMIFS('J1 Lijnen'!$J:$J,'J1 Lijnen'!$A:$A,$B16,'J1 Lijnen'!$K:$K,0.06) | Q16: =SUMIFS('J1 Lijnen'!$L:$L,'J1 Lijnen'!$A:$A,$B16,'J1 Lijnen'!$K:$K,0.06) | R16: =SUMIFS('J1 Lijnen'!$J:$J,'J1 Lijnen'!$A:$A,$B16,'J1 Lijnen'!$E:$E,"verpakking") | S16: =-SUMIFS('J1 Lijnen'!$J:$J,'J1 Lijnen'!$A:$A,$B16,'J1 Lijnen'!$E:$E,"financiële korting") | T16: =SUM(N16:S16) | X16: U2026-06 | Y16: =SUMIFS('J1 Journaal'!$K:$K,'J1 Journaal'!$E:$E,$B16)-SUMIFS('J1 Journaal'!$L:$L,'J1 Journaal'!$E:$E,$B16)
A17: 7 | B17: CA2 | C17: VERPLICHT | D17: K1 | E17: CN-AK | F17: retour | G17: 46069 | I17: HH-CN-26-004 | J17: HelmHuis bv | K17: Fietsatelier Noor bv | L17: HH-26-077 | M17: 10 sloten beschadigd geleverd, teruggestuurd | N17: =SUMIFS('J1 Lijnen'!$J:$J,'J1 Lijnen'!$A:$A,$B17,'J1 Lijnen'!$K:$K,0.21,'J1 Lijnen'!$E:$E,"<>verpakking") | O17: =SUMIFS('J1 Lijnen'!$L:$L,'J1 Lijnen'!$A:$A,$B17,'J1 Lijnen'!$K:$K,0.21) | P17: =SUMIFS('J1 Lijnen'!$J:$J,'J1 Lijnen'!$A:$A,$B17,'J1 Lijnen'!$K:$K,0.06) | Q17: =SUMIFS('J1 Lijnen'!$L:$L,'J1 Lijnen'!$A:$A,$B17,'J1 Lijnen'!$K:$K,0.06) | R17: =SUMIFS('J1 Lijnen'!$J:$J,'J1 Lijnen'!$A:$A,$B17,'J1 Lijnen'!$E:$E,"verpakking") | S17: =-SUMIFS('J1 Lijnen'!$J:$J,'J1 Lijnen'!$A:$A,$B17,'J1 Lijnen'!$E:$E,"financiële korting") | T17: =SUM(N17:S17) | X17: U2026-05 | Y17: =SUMIFS('J1 Journaal'!$K:$K,'J1 Journaal'!$E:$E,$B17)-SUMIFS('J1 Journaal'!$L:$L,'J1 Journaal'!$E:$E,$B17)
A18: 8 | B18: CA3 | C18: VERPLICHT | D18: K1 | E18: CN-AK | F18: retour | G18: 46078 | I18: SW-CN-118 | J18: Spaakwerk bv | K18: Fietsatelier Noor bv | L18: SW-1032 | M18: 10 kettingen van het verkeerde type, teruggestuurd (factuur was al betaald) | N18: =SUMIFS('J1 Lijnen'!$J:$J,'J1 Lijnen'!$A:$A,$B18,'J1 Lijnen'!$K:$K,0.21,'J1 Lijnen'!$E:$E,"<>verpakking") | O18: =SUMIFS('J1 Lijnen'!$L:$L,'J1 Lijnen'!$A:$A,$B18,'J1 Lijnen'!$K:$K,0.21) | P18: =SUMIFS('J1 Lijnen'!$J:$J,'J1 Lijnen'!$A:$A,$B18,'J1 Lijnen'!$K:$K,0.06) | Q18: =SUMIFS('J1 Lijnen'!$L:$L,'J1 Lijnen'!$A:$A,$B18,'J1 Lijnen'!$K:$K,0.06) | R18: =SUMIFS('J1 Lijnen'!$J:$J,'J1 Lijnen'!$A:$A,$B18,'J1 Lijnen'!$E:$E,"verpakking") | S18: =-SUMIFS('J1 Lijnen'!$J:$J,'J1 Lijnen'!$A:$A,$B18,'J1 Lijnen'!$E:$E,"financiële korting") | T18: =SUM(N18:S18) | X18: U2026-07 | Y18: =SUMIFS('J1 Journaal'!$K:$K,'J1 Journaal'!$E:$E,$B18)-SUMIFS('J1 Journaal'!$L:$L,'J1 Journaal'!$E:$E,$B18)
A19: 9 | B19: V1 | C19: VERPLICHT | D19: K1 | E19: VK | F19: handelsgoederen | G19: 46056 | H19: =G19+30 | I19: 2026-003 | J19: Fietsatelier Noor bv | K19: Velocity Deelfietsen bv | N19: =SUMIFS('J1 Lijnen'!$J:$J,'J1 Lijnen'!$A:$A,$B19,'J1 Lijnen'!$K:$K,0.21,'J1 Lijnen'!$E:$E,"<>verpakking") | O19: =SUMIFS('J1 Lijnen'!$L:$L,'J1 Lijnen'!$A:$A,$B19,'J1 Lijnen'!$K:$K,0.21) | P19: =SUMIFS('J1 Lijnen'!$J:$J,'J1 Lijnen'!$A:$A,$B19,'J1 Lijnen'!$K:$K,0.06) | Q19: =SUMIFS('J1 Lijnen'!$L:$L,'J1 Lijnen'!$A:$A,$B19,'J1 Lijnen'!$K:$K,0.06) | R19: =SUMIFS('J1 Lijnen'!$J:$J,'J1 Lijnen'!$A:$A,$B19,'J1 Lijnen'!$E:$E,"verpakking") | S19: =-SUMIFS('J1 Lijnen'!$J:$J,'J1 Lijnen'!$A:$A,$B19,'J1 Lijnen'!$E:$E,"financiële korting") | T19: =SUM(N19:S19) | X19: U2026-06 | Y19: =SUMIFS('J1 Journaal'!$K:$K,'J1 Journaal'!$E:$E,$B19)-SUMIFS('J1 Journaal'!$L:$L,'J1 Journaal'!$E:$E,$B19)
A20: 10 | B20: V2 | C20: VERPLICHT | D20: K1 | E20: VK | F20: handelsgoederen | G20: 46063 | H20: =G20+30 | I20: 2026-004 | J20: Fietsatelier Noor bv | K20: Bouwbedrijf Janssens & Zonen bv | N20: =SUMIFS('J1 Lijnen'!$J:$J,'J1 Lijnen'!$A:$A,$B20,'J1 Lijnen'!$K:$K,0.21,'J1 Lijnen'!$E:$E,"<>verpakking") | O20: =SUMIFS('J1 Lijnen'!$L:$L,'J1 Lijnen'!$A:$A,$B20,'J1 Lijnen'!$K:$K,0.21) | P20: =SUMIFS('J1 Lijnen'!$J:$J,'J1 Lijnen'!$A:$A,$B20,'J1 Lijnen'!$K:$K,0.06) | Q20: =SUMIFS('J1 Lijnen'!$L:$L,'J1 Lijnen'!$A:$A,$B20,'J1 Lijnen'!$K:$K,0.06) | R20: =SUMIFS('J1 Lijnen'!$J:$J,'J1 Lijnen'!$A:$A,$B20,'J1 Lijnen'!$E:$E,"verpakking") | S20: =-SUMIFS('J1 Lijnen'!$J:$J,'J1 Lijnen'!$A:$A,$B20,'J1 Lijnen'!$E:$E,"financiële korting") | T20: =SUM(N20:S20) | X20: U2026-05 | Y20: =SUMIFS('J1 Journaal'!$K:$K,'J1 Journaal'!$E:$E,$B20)-SUMIFS('J1 Journaal'!$L:$L,'J1 Journaal'!$E:$E,$B20)
A21: 11 | B21: V3 | C21: VERPLICHT | D21: K1 | E21: VK | F21: handelsgoederen | G21: 46065 | H21: =G21+30 | I21: 2026-005 | J21: Fietsatelier Noor bv | K21: Architectenbureau Dubois srl | N21: =SUMIFS('J1 Lijnen'!$J:$J,'J1 Lijnen'!$A:$A,$B21,'J1 Lijnen'!$K:$K,0.21,'J1 Lijnen'!$E:$E,"<>verpakking") | O21: =SUMIFS('J1 Lijnen'!$L:$L,'J1 Lijnen'!$A:$A,$B21,'J1 Lijnen'!$K:$K,0.21) | P21: =SUMIFS('J1 Lijnen'!$J:$J,'J1 Lijnen'!$A:$A,$B21,'J1 Lijnen'!$K:$K,0.06) | Q21: =SUMIFS('J1 Lijnen'!$L:$L,'J1 Lijnen'!$A:$A,$B21,'J1 Lijnen'!$K:$K,0.06) | R21: =SUMIFS('J1 Lijnen'!$J:$J,'J1 Lijnen'!$A:$A,$B21,'J1 Lijnen'!$E:$E,"verpakking") | S21: =-SUMIFS('J1 Lijnen'!$J:$J,'J1 Lijnen'!$A:$A,$B21,'J1 Lijnen'!$E:$E,"financiële korting") | T21: =SUM(N21:S21) | X21: U2026-06 | Y21: =SUMIFS('J1 Journaal'!$K:$K,'J1 Journaal'!$E:$E,$B21)-SUMIFS('J1 Journaal'!$L:$L,'J1 Journaal'!$E:$E,$B21)
A22: 12 | B22: V4 | C22: VERPLICHT | D22: K1 | E22: VK | F22: herstellingen | G22: 46070 | H22: =G22+30 | I22: 2026-006 | J22: Fietsatelier Noor bv | K22: Snelpost bv | N22: =SUMIFS('J1 Lijnen'!$J:$J,'J1 Lijnen'!$A:$A,$B22,'J1 Lijnen'!$K:$K,0.21,'J1 Lijnen'!$E:$E,"<>verpakking") | O22: =SUMIFS('J1 Lijnen'!$L:$L,'J1 Lijnen'!$A:$A,$B22,'J1 Lijnen'!$K:$K,0.21) | P22: =SUMIFS('J1 Lijnen'!$J:$J,'J1 Lijnen'!$A:$A,$B22,'J1 Lijnen'!$K:$K,0.06) | Q22: =SUMIFS('J1 Lijnen'!$L:$L,'J1 Lijnen'!$A:$A,$B22,'J1 Lijnen'!$K:$K,0.06) | R22: =SUMIFS('J1 Lijnen'!$J:$J,'J1 Lijnen'!$A:$A,$B22,'J1 Lijnen'!$E:$E,"verpakking") | S22: =-SUMIFS('J1 Lijnen'!$J:$J,'J1 Lijnen'!$A:$A,$B22,'J1 Lijnen'!$E:$E,"financiële korting") | T22: =SUM(N22:S22) | X22: U2026-07 | Y22: =SUMIFS('J1 Journaal'!$K:$K,'J1 Journaal'!$E:$E,$B22)-SUMIFS('J1 Journaal'!$L:$L,'J1 Journaal'!$E:$E,$B22)
A23: 13 | B23: V5 | C23: VERPLICHT | D23: K1 | E23: VK | F23: handelsgoederen | G23: 46072 | H23: =G23+30 | I23: 2026-007 | J23: Fietsatelier Noor bv | K23: Koffiebar Da Silva | N23: =SUMIFS('J1 Lijnen'!$J:$J,'J1 Lijnen'!$A:$A,$B23,'J1 Lijnen'!$K:$K,0.21,'J1 Lijnen'!$E:$E,"<>verpakking") | O23: =SUMIFS('J1 Lijnen'!$L:$L,'J1 Lijnen'!$A:$A,$B23,'J1 Lijnen'!$K:$K,0.21) | P23: =SUMIFS('J1 Lijnen'!$J:$J,'J1 Lijnen'!$A:$A,$B23,'J1 Lijnen'!$K:$K,0.06) | Q23: =SUMIFS('J1 Lijnen'!$L:$L,'J1 Lijnen'!$A:$A,$B23,'J1 Lijnen'!$K:$K,0.06) | R23: =SUMIFS('J1 Lijnen'!$J:$J,'J1 Lijnen'!$A:$A,$B23,'J1 Lijnen'!$E:$E,"verpakking") | S23: =-SUMIFS('J1 Lijnen'!$J:$J,'J1 Lijnen'!$A:$A,$B23,'J1 Lijnen'!$E:$E,"financiële korting") | T23: =SUM(N23:S23) | X23: U2026-07 | Y23: =SUMIFS('J1 Journaal'!$K:$K,'J1 Journaal'!$E:$E,$B23)-SUMIFS('J1 Journaal'!$L:$L,'J1 Journaal'!$E:$E,$B23)
A24: 14 | B24: CV1 | C24: VERPLICHT | D24: K1 | E24: CN-VK | F24: retour | G24: 46073 | I24: CN-2026-002 | J24: Fietsatelier Noor bv | K24: Velocity Deelfietsen bv | L24: 2026-003 | M24: 1 fiets met defecte versnelling teruggenomen | N24: =SUMIFS('J1 Lijnen'!$J:$J,'J1 Lijnen'!$A:$A,$B24,'J1 Lijnen'!$K:$K,0.21,'J1 Lijnen'!$E:$E,"<>verpakking") | O24: =SUMIFS('J1 Lijnen'!$L:$L,'J1 Lijnen'!$A:$A,$B24,'J1 Lijnen'!$K:$K,0.21) | P24: =SUMIFS('J1 Lijnen'!$J:$J,'J1 Lijnen'!$A:$A,$B24,'J1 Lijnen'!$K:$K,0.06) | Q24: =SUMIFS('J1 Lijnen'!$L:$L,'J1 Lijnen'!$A:$A,$B24,'J1 Lijnen'!$K:$K,0.06) | R24: =SUMIFS('J1 Lijnen'!$J:$J,'J1 Lijnen'!$A:$A,$B24,'J1 Lijnen'!$E:$E,"verpakking") | S24: =-SUMIFS('J1 Lijnen'!$J:$J,'J1 Lijnen'!$A:$A,$B24,'J1 Lijnen'!$E:$E,"financiële korting") | T24: =SUM(N24:S24) | X24: U2026-06 | Y24: =SUMIFS('J1 Journaal'!$K:$K,'J1 Journaal'!$E:$E,$B24)-SUMIFS('J1 Journaal'!$L:$L,'J1 Journaal'!$E:$E,$B24)
A25: 15 | B25: CV2 | C25: VERPLICHT | D25: K1 | E25: CN-VK | F25: retour | G25: 46076 | I25: CN-2026-003 | J25: Fietsatelier Noor bv | K25: Koffiebar Da Silva | L25: 2026-007 | M25: 2 helmen in de verkeerde maat teruggebracht | N25: =SUMIFS('J1 Lijnen'!$J:$J,'J1 Lijnen'!$A:$A,$B25,'J1 Lijnen'!$K:$K,0.21,'J1 Lijnen'!$E:$E,"<>verpakking") | O25: =SUMIFS('J1 Lijnen'!$L:$L,'J1 Lijnen'!$A:$A,$B25,'J1 Lijnen'!$K:$K,0.21) | P25: =SUMIFS('J1 Lijnen'!$J:$J,'J1 Lijnen'!$A:$A,$B25,'J1 Lijnen'!$K:$K,0.06) | Q25: =SUMIFS('J1 Lijnen'!$L:$L,'J1 Lijnen'!$A:$A,$B25,'J1 Lijnen'!$K:$K,0.06) | R25: =SUMIFS('J1 Lijnen'!$J:$J,'J1 Lijnen'!$A:$A,$B25,'J1 Lijnen'!$E:$E,"verpakking") | S25: =-SUMIFS('J1 Lijnen'!$J:$J,'J1 Lijnen'!$A:$A,$B25,'J1 Lijnen'!$E:$E,"financiële korting") | T25: =SUM(N25:S25) | X25: U2026-07 | Y25: =SUMIFS('J1 Journaal'!$K:$K,'J1 Journaal'!$E:$E,$B25)-SUMIFS('J1 Journaal'!$L:$L,'J1 Journaal'!$E:$E,$B25)
A26: 16 | B26: CV3 | C26: VERPLICHT | D26: K1 | E26: CN-VK | F26: retour | G26: 46083 | I26: CN-2026-004 | J26: Fietsatelier Noor bv | K26: Architectenbureau Dubois srl | L26: 2026-005 | M26: 1 e-bike met defecte batterij teruggenomen (factuur was al betaald) | N26: =SUMIFS('J1 Lijnen'!$J:$J,'J1 Lijnen'!$A:$A,$B26,'J1 Lijnen'!$K:$K,0.21,'J1 Lijnen'!$E:$E,"<>verpakking") | O26: =SUMIFS('J1 Lijnen'!$L:$L,'J1 Lijnen'!$A:$A,$B26,'J1 Lijnen'!$K:$K,0.21) | P26: =SUMIFS('J1 Lijnen'!$J:$J,'J1 Lijnen'!$A:$A,$B26,'J1 Lijnen'!$K:$K,0.06) | Q26: =SUMIFS('J1 Lijnen'!$L:$L,'J1 Lijnen'!$A:$A,$B26,'J1 Lijnen'!$K:$K,0.06) | R26: =SUMIFS('J1 Lijnen'!$J:$J,'J1 Lijnen'!$A:$A,$B26,'J1 Lijnen'!$E:$E,"verpakking") | S26: =-SUMIFS('J1 Lijnen'!$J:$J,'J1 Lijnen'!$A:$A,$B26,'J1 Lijnen'!$E:$E,"financiële korting") | T26: =SUM(N26:S26) | X26: U2026-07 | Y26: =SUMIFS('J1 Journaal'!$K:$K,'J1 Journaal'!$E:$E,$B26)-SUMIFS('J1 Journaal'!$L:$L,'J1 Journaal'!$E:$E,$B26)
A27: 17 | B27: D1 | C27: VERPLICHT | D27: K1 | E27: DO | F27: dagontvangst | G27: 46060 | I27: DO-2026-02 | J27: Fietsatelier Noor bv | K27: particulieren (kasticket) | M27: Dagontvangsten winkel (verkopen aan particulieren) | N27: =SUMIFS('J1 Lijnen'!$J:$J,'J1 Lijnen'!$A:$A,$B27,'J1 Lijnen'!$K:$K,0.21,'J1 Lijnen'!$E:$E,"<>verpakking") | O27: =SUMIFS('J1 Lijnen'!$L:$L,'J1 Lijnen'!$A:$A,$B27,'J1 Lijnen'!$K:$K,0.21) | P27: =SUMIFS('J1 Lijnen'!$J:$J,'J1 Lijnen'!$A:$A,$B27,'J1 Lijnen'!$K:$K,0.06) | Q27: =SUMIFS('J1 Lijnen'!$L:$L,'J1 Lijnen'!$A:$A,$B27,'J1 Lijnen'!$K:$K,0.06) | R27: =SUMIFS('J1 Lijnen'!$J:$J,'J1 Lijnen'!$A:$A,$B27,'J1 Lijnen'!$E:$E,"verpakking") | S27: =-SUMIFS('J1 Lijnen'!$J:$J,'J1 Lijnen'!$A:$A,$B27,'J1 Lijnen'!$E:$E,"financiële korting") | T27: =SUM(N27:S27) | V27: =T27-W27 | W27: 1500 | X27: D1K, U2026-04 | Y27: =SUMIFS('J1 Journaal'!$K:$K,'J1 Journaal'!$E:$E,$B27)-SUMIFS('J1 Journaal'!$L:$L,'J1 Journaal'!$E:$E,$B27)
A28: 18 | B28: D1K | C28: VERPLICHT | D28: K1 | E28: KAS | F28: ontvangst | G28: 46060 | I28: Kasboek DO-2026-02 | J28: Fietsatelier Noor bv | K28: Fietsatelier Noor bv | L28: DO-2026-02 | M28: Contant deel van dagontvangst DO-2026-02 (laat de vordering op de klanten dalen) | T28: 633 | V28: 633 | Y28: =SUMIFS('J1 Journaal'!$K:$K,'J1 Journaal'!$E:$E,$B28)-SUMIFS('J1 Journaal'!$L:$L,'J1 Journaal'!$E:$E,$B28)
A29: 19 | B29: D2 | C29: VERPLICHT | D29: K1 | E29: DO | F29: dagontvangst | G29: 46067 | I29: DO-2026-03 | J29: Fietsatelier Noor bv | K29: particulieren (kasticket) | M29: Dagontvangsten winkel (verkopen aan particulieren) | N29: =SUMIFS('J1 Lijnen'!$J:$J,'J1 Lijnen'!$A:$A,$B29,'J1 Lijnen'!$K:$K,0.21,'J1 Lijnen'!$E:$E,"<>verpakking") | O29: =SUMIFS('J1 Lijnen'!$L:$L,'J1 Lijnen'!$A:$A,$B29,'J1 Lijnen'!$K:$K,0.21) | P29: =SUMIFS('J1 Lijnen'!$J:$J,'J1 Lijnen'!$A:$A,$B29,'J1 Lijnen'!$K:$K,0.06) | Q29: =SUMIFS('J1 Lijnen'!$L:$L,'J1 Lijnen'!$A:$A,$B29,'J1 Lijnen'!$K:$K,0.06) | R29: =SUMIFS('J1 Lijnen'!$J:$J,'J1 Lijnen'!$A:$A,$B29,'J1 Lijnen'!$E:$E,"verpakking") | S29: =-SUMIFS('J1 Lijnen'!$J:$J,'J1 Lijnen'!$A:$A,$B29,'J1 Lijnen'!$E:$E,"financiële korting") | T29: =SUM(N29:S29) | V29: =T29-W29 | W29: 2500 | X29: D2K, U2026-05 | Y29: =SUMIFS('J1 Journaal'!$K:$K,'J1 Journaal'!$E:$E,$B29)-SUMIFS('J1 Journaal'!$L:$L,'J1 Journaal'!$E:$E,$B29)
A30: 20 | B30: D2K | C30: VERPLICHT | D30: K1 | E30: KAS | F30: ontvangst | G30: 46067 | I30: Kasboek DO-2026-03 | J30: Fietsatelier Noor bv | K30: Fietsatelier Noor bv | L30: DO-2026-03 | M30: Contant deel van dagontvangst DO-2026-03 (laat de vordering op de klanten dalen) | T30: 344 | V30: 344 | Y30: =SUMIFS('J1 Journaal'!$K:$K,'J1 Journaal'!$E:$E,$B30)-SUMIFS('J1 Journaal'!$L:$L,'J1 Journaal'!$E:$E,$B30)
A31: 21 | B31: D3 | C31: VERPLICHT | D31: K1 | E31: DO | F31: dagontvangst | G31: 46074 | I31: DO-2026-04 | J31: Fietsatelier Noor bv | K31: particulieren (kasticket) | M31: Dagontvangsten winkel (verkopen aan particulieren) | N31: =SUMIFS('J1 Lijnen'!$J:$J,'J1 Lijnen'!$A:$A,$B31,'J1 Lijnen'!$K:$K,0.21,'J1 Lijnen'!$E:$E,"<>verpakking") | O31: =SUMIFS('J1 Lijnen'!$L:$L,'J1 Lijnen'!$A:$A,$B31,'J1 Lijnen'!$K:$K,0.21) | P31: =SUMIFS('J1 Lijnen'!$J:$J,'J1 Lijnen'!$A:$A,$B31,'J1 Lijnen'!$K:$K,0.06) | Q31: =SUMIFS('J1 Lijnen'!$L:$L,'J1 Lijnen'!$A:$A,$B31,'J1 Lijnen'!$K:$K,0.06) | R31: =SUMIFS('J1 Lijnen'!$J:$J,'J1 Lijnen'!$A:$A,$B31,'J1 Lijnen'!$E:$E,"verpakking") | S31: =-SUMIFS('J1 Lijnen'!$J:$J,'J1 Lijnen'!$A:$A,$B31,'J1 Lijnen'!$E:$E,"financiële korting") | T31: =SUM(N31:S31) | V31: =T31-W31 | W31: 1000 | X31: D3K, U2026-06 | Y31: =SUMIFS('J1 Journaal'!$K:$K,'J1 Journaal'!$E:$E,$B31)-SUMIFS('J1 Journaal'!$L:$L,'J1 Journaal'!$E:$E,$B31)
A32: 22 | B32: D3K | C32: VERPLICHT | D32: K1 | E32: KAS | F32: ontvangst | G32: 46074 | I32: Kasboek DO-2026-04 | J32: Fietsatelier Noor bv | K32: Fietsatelier Noor bv | L32: DO-2026-04 | M32: Contant deel van dagontvangst DO-2026-04 (laat de vordering op de klanten dalen) | T32: 354 | V32: 354 | Y32: =SUMIFS('J1 Journaal'!$K:$K,'J1 Journaal'!$E:$E,$B32)-SUMIFS('J1 Journaal'!$L:$L,'J1 Journaal'!$E:$E,$B32)
A33: 1 | B33: Q2A1 | C33: OEFEN | D33: K2 | E33: AK | F33: handelsgoederen | G33: 46114 | H33: =G33+30 | I33: 2026-411 | J33: Velomax bv | K33: Fietsatelier Noor bv | N33: =SUMIFS('J1 Lijnen'!$J:$J,'J1 Lijnen'!$A:$A,$B33,'J1 Lijnen'!$K:$K,0.21,'J1 Lijnen'!$E:$E,"<>verpakking") | O33: =SUMIFS('J1 Lijnen'!$L:$L,'J1 Lijnen'!$A:$A,$B33,'J1 Lijnen'!$K:$K,0.21) | P33: =SUMIFS('J1 Lijnen'!$J:$J,'J1 Lijnen'!$A:$A,$B33,'J1 Lijnen'!$K:$K,0.06) | Q33: =SUMIFS('J1 Lijnen'!$L:$L,'J1 Lijnen'!$A:$A,$B33,'J1 Lijnen'!$K:$K,0.06) | R33: =SUMIFS('J1 Lijnen'!$J:$J,'J1 Lijnen'!$A:$A,$B33,'J1 Lijnen'!$E:$E,"verpakking") | S33: =-SUMIFS('J1 Lijnen'!$J:$J,'J1 Lijnen'!$A:$A,$B33,'J1 Lijnen'!$E:$E,"financiële korting") | T33: =SUM(N33:S33) | X33: U2026-08 | Y33: =SUMIFS('J1 Journaal'!$K:$K,'J1 Journaal'!$E:$E,$B33)-SUMIFS('J1 Journaal'!$L:$L,'J1 Journaal'!$E:$E,$B33)
A34: 2 | B34: Q2A2 | C34: OEFEN | D34: K2 | E34: AK | F34: diensten | G34: 46120 | H34: =G34+30 | I34: SK-26-1290 | J34: Stroomkracht nv | K34: Fietsatelier Noor bv | N34: =SUMIFS('J1 Lijnen'!$J:$J,'J1 Lijnen'!$A:$A,$B34,'J1 Lijnen'!$K:$K,0.21,'J1 Lijnen'!$E:$E,"<>verpakking") | O34: =SUMIFS('J1 Lijnen'!$L:$L,'J1 Lijnen'!$A:$A,$B34,'J1 Lijnen'!$K:$K,0.21) | P34: =SUMIFS('J1 Lijnen'!$J:$J,'J1 Lijnen'!$A:$A,$B34,'J1 Lijnen'!$K:$K,0.06) | Q34: =SUMIFS('J1 Lijnen'!$L:$L,'J1 Lijnen'!$A:$A,$B34,'J1 Lijnen'!$K:$K,0.06) | R34: =SUMIFS('J1 Lijnen'!$J:$J,'J1 Lijnen'!$A:$A,$B34,'J1 Lijnen'!$E:$E,"verpakking") | S34: =-SUMIFS('J1 Lijnen'!$J:$J,'J1 Lijnen'!$A:$A,$B34,'J1 Lijnen'!$E:$E,"financiële korting") | T34: =SUM(N34:S34) | X34: U2026-08 | Y34: =SUMIFS('J1 Journaal'!$K:$K,'J1 Journaal'!$E:$E,$B34)-SUMIFS('J1 Journaal'!$L:$L,'J1 Journaal'!$E:$E,$B34)
A35: 3 | B35: Q2V1 | C35: OEFEN | D35: K2 | E35: VK | F35: handelsgoederen | G35: 46122 | H35: =G35+30 | I35: 2026-008 | J35: Fietsatelier Noor bv | K35: Camping De Vlinder bv | N35: =SUMIFS('J1 Lijnen'!$J:$J,'J1 Lijnen'!$A:$A,$B35,'J1 Lijnen'!$K:$K,0.21,'J1 Lijnen'!$E:$E,"<>verpakking") | O35: =SUMIFS('J1 Lijnen'!$L:$L,'J1 Lijnen'!$A:$A,$B35,'J1 Lijnen'!$K:$K,0.21) | P35: =SUMIFS('J1 Lijnen'!$J:$J,'J1 Lijnen'!$A:$A,$B35,'J1 Lijnen'!$K:$K,0.06) | Q35: =SUMIFS('J1 Lijnen'!$L:$L,'J1 Lijnen'!$A:$A,$B35,'J1 Lijnen'!$K:$K,0.06) | R35: =SUMIFS('J1 Lijnen'!$J:$J,'J1 Lijnen'!$A:$A,$B35,'J1 Lijnen'!$E:$E,"verpakking") | S35: =-SUMIFS('J1 Lijnen'!$J:$J,'J1 Lijnen'!$A:$A,$B35,'J1 Lijnen'!$E:$E,"financiële korting") | T35: =SUM(N35:S35) | X35: U2026-08 | Y35: =SUMIFS('J1 Journaal'!$K:$K,'J1 Journaal'!$E:$E,$B35)-SUMIFS('J1 Journaal'!$L:$L,'J1 Journaal'!$E:$E,$B35)
A36: 4 | B36: Q2CA1 | C36: OEFEN | D36: K2 | E36: CN-AK | F36: retour | G36: 46124 | I36: CN-2026-029 | J36: Velomax bv | K36: Fietsatelier Noor bv | L36: 2026-411 | M36: 2 kinderfietsen in de verkeerde kleur, teruggestuurd | N36: =SUMIFS('J1 Lijnen'!$J:$J,'J1 Lijnen'!$A:$A,$B36,'J1 Lijnen'!$K:$K,0.21,'J1 Lijnen'!$E:$E,"<>verpakking") | O36: =SUMIFS('J1 Lijnen'!$L:$L,'J1 Lijnen'!$A:$A,$B36,'J1 Lijnen'!$K:$K,0.21) | P36: =SUMIFS('J1 Lijnen'!$J:$J,'J1 Lijnen'!$A:$A,$B36,'J1 Lijnen'!$K:$K,0.06) | Q36: =SUMIFS('J1 Lijnen'!$L:$L,'J1 Lijnen'!$A:$A,$B36,'J1 Lijnen'!$K:$K,0.06) | R36: =SUMIFS('J1 Lijnen'!$J:$J,'J1 Lijnen'!$A:$A,$B36,'J1 Lijnen'!$E:$E,"verpakking") | S36: =-SUMIFS('J1 Lijnen'!$J:$J,'J1 Lijnen'!$A:$A,$B36,'J1 Lijnen'!$E:$E,"financiële korting") | T36: =SUM(N36:S36) | X36: U2026-08 | Y36: =SUMIFS('J1 Journaal'!$K:$K,'J1 Journaal'!$E:$E,$B36)-SUMIFS('J1 Journaal'!$L:$L,'J1 Journaal'!$E:$E,$B36)
A37: 5 | B37: Q2CV1 | C37: OEFEN | D37: K2 | E37: CN-VK | F37: retour | G37: 46127 | I37: CN-2026-005 | J37: Fietsatelier Noor bv | K37: Camping De Vlinder bv | L37: 2026-008 | M37: 2 helmen te veel geleverd, teruggebracht | N37: =SUMIFS('J1 Lijnen'!$J:$J,'J1 Lijnen'!$A:$A,$B37,'J1 Lijnen'!$K:$K,0.21,'J1 Lijnen'!$E:$E,"<>verpakking") | O37: =SUMIFS('J1 Lijnen'!$L:$L,'J1 Lijnen'!$A:$A,$B37,'J1 Lijnen'!$K:$K,0.21) | P37: =SUMIFS('J1 Lijnen'!$J:$J,'J1 Lijnen'!$A:$A,$B37,'J1 Lijnen'!$K:$K,0.06) | Q37: =SUMIFS('J1 Lijnen'!$L:$L,'J1 Lijnen'!$A:$A,$B37,'J1 Lijnen'!$K:$K,0.06) | R37: =SUMIFS('J1 Lijnen'!$J:$J,'J1 Lijnen'!$A:$A,$B37,'J1 Lijnen'!$E:$E,"verpakking") | S37: =-SUMIFS('J1 Lijnen'!$J:$J,'J1 Lijnen'!$A:$A,$B37,'J1 Lijnen'!$E:$E,"financiële korting") | T37: =SUM(N37:S37) | X37: U2026-08 | Y37: =SUMIFS('J1 Journaal'!$K:$K,'J1 Journaal'!$E:$E,$B37)-SUMIFS('J1 Journaal'!$L:$L,'J1 Journaal'!$E:$E,$B37)
A38: 6 | B38: Q2A3 | C38: OEFEN | D38: K2 | E38: AK | F38: vaste activa | G38: 46129 | H38: =G38+30 | I38: DW-2026-087 | J38: Deprez Werkplaatsinrichting bv | K38: Fietsatelier Noor bv | N38: =SUMIFS('J1 Lijnen'!$J:$J,'J1 Lijnen'!$A:$A,$B38,'J1 Lijnen'!$K:$K,0.21,'J1 Lijnen'!$E:$E,"<>verpakking") | O38: =SUMIFS('J1 Lijnen'!$L:$L,'J1 Lijnen'!$A:$A,$B38,'J1 Lijnen'!$K:$K,0.21) | P38: =SUMIFS('J1 Lijnen'!$J:$J,'J1 Lijnen'!$A:$A,$B38,'J1 Lijnen'!$K:$K,0.06) | Q38: =SUMIFS('J1 Lijnen'!$L:$L,'J1 Lijnen'!$A:$A,$B38,'J1 Lijnen'!$K:$K,0.06) | R38: =SUMIFS('J1 Lijnen'!$J:$J,'J1 Lijnen'!$A:$A,$B38,'J1 Lijnen'!$E:$E,"verpakking") | S38: =-SUMIFS('J1 Lijnen'!$J:$J,'J1 Lijnen'!$A:$A,$B38,'J1 Lijnen'!$E:$E,"financiële korting") | T38: =SUM(N38:S38) | X38: U2026-09 | Y38: =SUMIFS('J1 Journaal'!$K:$K,'J1 Journaal'!$E:$E,$B38)-SUMIFS('J1 Journaal'!$L:$L,'J1 Journaal'!$E:$E,$B38)
